Workbook

Sheet CID
B1: NOVEMBRE | E1: DICEMBRE | H1: GENNAIO | K1: FEBBRAIO | N1: MARZO | Q1: APRILE
B2: € | C2: ORE | D2: €/ORE | E2: € | F2: ORE | G2: €/ORE | H2: € | I2: ORE | J2: €/ORE | K2: € | L2: ORE | M2: €/ORE | N2: € | O2: ORE | P2: €/ORE | Q2: € | R2: ORE | S2: €/ORE
A3: Endri Vora | B3: 422.17 | C3: 65 | D3: =B3/C3 -> 6.4949231 | E3: 0 | F3: 135 | G3: =E3/F3 -> 0 | K3: 405.32 | L3: 72 | M3: =K3/L3 -> 5.6294444
A4: Alessia De Nardi | B4: 547.35 | C4: 144 | D4: =B4/C4 -> 3.8010417 | E4: 615.76 | F4: 162 | G4: =E4/F4 -> 3.8009877 | K4: 759.53 | L4: 144 | M4: =K4/L4 -> 5.2745139
A5: Daniele Diana | B5: 547.35 | C5: 144 | D5: =B5/C5 -> 3.8010417 | E5: 615.76 | F5: 162 | G5: =E5/F5 -> 3.8009877 | L5: 144 | M5: =K5/L5 -> 0
A6: Nicola Scarpa | B6: 525.55 | C6: 78 | D6: =B6/C6 -> 6.7378205 | E6: 0 | F6: 162 | G6: =E6/F6 -> 0 | K6: 691.41 | L6: 120 | M6: =K6/L6 -> 5.76175
A7: Waldy Vasquez | B7: 547.35 | C7: 144 | D7: =B7/C7 -> 3.8010417 | E7: 615.76 | F7: 162 | G7: =E7/F7 -> 3.8009877 | L7: 144 | M7: =K7/L7 -> 0
A8: Vanessa Basso | B8: 547.35 | C8: 144 | D8: =B8/C8 -> 3.8010417 | E8: 615.76 | F8: 162 | G8: =E8/F8 -> 3.8009877 | K8: 759.53 | L8: 144 | M8: =K8/L8 -> 5.2745139
A9: Elena Battisti | B9: 0 | C9: 144 | D9: =B9/C9 -> 0 | E9: 0 | F9: 162 | G9: =E9/F9 -> 0 | L9: 0 | M9: =K9/L9 -> #DIV/0!
A10: Luca Casagrande | B10: 0 | C10: 39 | D10: =B10/C10 -> 0 | E10: 0 | F10: 39 | G10: =E10/F10 -> 0 | K10: 193.85 | L10: 36 | M10: =K10/L10 -> 5.3847222
A11: Francesko Xhaja | B11: 0 | C11: 18 | D11: =B11/C11 -> 0 | E11: 0 | F11: 8 | G11: =E11/F11 -> 0 | L11: 0 | M11: =K11/L11 -> #DIV/0!
A12: Sara Rimolo | B12: 0 | C12: 78 | D12: =B12/C12 -> 0 | E12: 0 | F12: 162 | G12: =E12/F12 -> 0 | K12: 540.43 | L12: 96 | M12: =K12/L12 -> 5.6294792
A13: Melissa Pongan | B13: 0 | C13: 72 | D13: =B13/C13 -> 0
B14: =SUM(B3:B13) -> 3137.12 | E14: =SUM(E3:E12) -> 2463.04 | H14: =SUM(H3:H12) -> 0 | K14: =SUM(K3:K12) -> 3350.07 | N14: =SUM(N3:N12) -> 0 | Q14: =SUM(Q3:Q12) -> 0
A18: 01/11/20 - 27/12/20 | B18: 20347.2 | C18: 2512 | D18: 11
A19: 01/02/21 - 25/04/21 | B19: 32510.52 | C19: 3492 | D19: 9

Sheet DASHBOARD
AF2: AGGIUNGERE INCIDENZA DEI COSTI
C3: FATTURATO | I3: SALDO IVA | O3: UTILE | U3: LIQUIDITÀ | AA3: DATI MEDI | AF3: AGGIUNGERE MOL E EBIT
C5: ='BUDGET 25'!AB5 -> 734081.72 | I5: ='BILANCIO 25'!C105 -> 43462.66 | O5: ='BUDGET 25'!AB3 -> #N/A | U5: =CASSA!D4+BANCA!D4 -> 150224.35
AA6: FATTURATO
AA8: Giornaliero
AA9: 2742.8354
AA11: Mensile
AA12: =AVERAGEIF(STORICO!C4:C15,"<>0",STORICO!C4:C15) -> 84427.418
AA15: UTILE
AA17: Giornaliero
AA18: 678.36972
AA20: Mensile
AA21: 18400.779
AA26: LABOR COST
AA28: ='BUDGET 25'!AC12 -> 0.29881943
AA30: F&B COST
AA32: ='BUDGET 25'!AC13 -> 0.42031675
AA34: MOL
AA36: =('BUDGET 25'!AB5-'BUDGET 25'!AB12-'BUDGET 25'!AB13-'BUDGET 25'!AB15-'BUDGET 25'!AB16)/'BUDGET 25'!AB5 -> 0.020254107
AA38: EBIT
AA40: =('BUDGET 25'!AB3)/'BUDGET 25'!AB5 -> #N/A

Sheet CALENDARIO 2025
A1: Gennaio | D1: Febbraio | G1: Marzo | J1: Aprile | M1: Maggio | P1: Giugno | S1: Luglio | V1: Agosto | Y1: Settembre | AB1: Ottobre | AE1: Novembre | AH1: Dicembre
A2: 1 | B2: M | D2: 1 | E2: S | G2: 1 | H2: S | I2: APERTURA VILLA VARDA | J2: 1 | K2: M | M2: 1 | N2: G | O2: BOTANICO | P2: 1 | Q2: D | R2: xtreme days | S2: 1 | T2: M | V2: 1 | W2: V | X2: MATTEO B - Guest DANIELI Bassano | Y2: 1 | Z2: L | AB2: 1 | AC2: M | AE2: 1 | AF2: S | AG2: QMD | AH2: 1 | AI2: L
A3: 2 | B3: G | D3: 2 | E3: D | F3: QMD | G3: 2 | H3: D | I3: QMD | J3: 2 | K3: M | M3: 2 | N3: V | P3: 2 | Q3: L | R3: xtreme days | S3: 2 | T3: M | V3: 2 | W3: S | Y3: 2 | Z3: M | AB3: 2 | AC3: G | AE3: 2 | AF3: D | AH3: 2 | AI3: M
A4: 3 | B4: V | D4: 3 | E4: L | G4: 3 | H4: L | J4: 3 | K4: G | M4: 3 | N4: S | P4: 3 | Q4: M | S4: 3 | T4: G | U4: CJF | V4: 3 | W4: D | Y4: 3 | Z4: M | AB4: 3 | AC4: V | AE4: 3 | AF4: L | AH4: 3 | AI4: M
A5: 4 | B5: S | D5: 4 | E5: M | G5: 4 | H5: M | J5: 4 | K5: V | M5: 4 | N5: D | P5: 4 | Q5: M | S5: 4 | T5: V | U5: SEBA - BUMBU CONF | V5: 4 | W5: L | Y5: 4 | Z5: G | AB5: 4 | AC5: S | AE5: 4 | AF5: M | AH5: 4 | AI5: G
A6: 5 | B6: D | D6: 5 | E6: M | G6: 5 | H6: M | J6: 5 | K6: S | M6: 5 | N6: L | P6: 5 | Q6: G | S6: 5 | T6: S | V6: 5 | W6: M | Y6: 5 | Z6: V | AA6: SEBA | AB6: 5 | AC6: D | AE6: 5 | AF6: M | AH6: 5 | AI6: V
A7: 6 | B7: L | C7: QMD | D7: 6 | E7: G | G7: 6 | H7: G | J7: 6 | K7: D | L7: QMD | M7: 6 | N7: M | P7: 6 | Q7: V | S7: 6 | T7: D | U7: PIANCA | V7: 6 | W7: M | Y7: 6 | Z7: S | AB7: 6 | AC7: L | AE7: 6 | AF7: G | AH7: 6 | AI7: S
A8: 7 | B8: M | D8: 7 | E8: V | G8: 7 | H8: V | J8: 7 | K8: L | M8: 7 | N8: M | P8: 7 | Q8: S | S8: 7 | T8: L | V8: 7 | W8: G | Y8: 7 | Z8: D | AA8: SAGRA DEI OSEI + BOTANICO | AB8: 7 | AC8: M | AE8: 7 | AF8: V | AH8: 7 | AI8: D | AJ8: QMD
A9: 8 | B9: M | D9: 8 | E9: S | G9: 8 | H9: S | J9: 8 | K9: M | M9: 8 | N9: G | P9: 8 | Q9: D | S9: 8 | T9: M | V9: 8 | W9: V | X9: BOCCALON - Don Julio / Casamigos | Y9: 8 | Z9: L | AB9: 8 | AC9: M | AE9: 8 | AF9: S | AH9: 8 | AI9: L
A10: 9 | B10: G | D10: 9 | E10: D | G10: 9 | H10: D | I10: BOTANICO | J10: 9 | K10: M | M10: 9 | N10: V | P10: 9 | Q10: L | S10: 9 | T10: M | V10: 9 | W10: S | Y10: 9 | Z10: M | AB10: 9 | AC10: G | AE10: 9 | AF10: D | AG10: MAINSTREAM | AH10: 9 | AI10: M
A11: 10 | B11: V | D11: 10 | E11: L | G11: 10 | H11: L | J11: 10 | K11: G | M11: 10 | N11: S | P11: 10 | Q11: M | S11: 10 | T11: G | V11: 10 | W11: D | X11: PIANCA | Y11: 10 | Z11: M | AB11: 10 | AC11: V | AE11: 10 | AF11: L | AH11: 10 | AI11: M
A12: 11 | B12: S | D12: 11 | E12: M | G12: 11 | H12: M | J12: 11 | K12: V | M12: 11 | N12: D | O12: S QUIRINO + BOT | P12: 11 | Q12: M | S12: 11 | T12: V | U12: NEGOZI APERTI + MOOKI - TANQ TEN CONF | V12: 11 | W12: L | Y12: 11 | Z12: G | AB12: 11 | AC12: S | AE12: 11 | AF12: M | AH12: 11 | AI12: G
A13: 12 | B13: D | D13: 12 | E13: M | G13: 12 | H13: M | J13: 12 | K13: S | M13: 12 | N13: L | P13: 12 | Q13: G | S13: 12 | T13: S | U13: ^^^^ MODULAR VV ^^^^ | V13: 12 | W13: M | X13: SOUND GARDEN VV | Y13: 12 | Z13: V | AA13: BOCCALON | AB13: 12 | AC13: D | AE13: 12 | AF13: M | AH13: 12 | AI13: V
A14: 13 | B14: L | D14: 13 | E14: G | G14: 13 | H14: G | J14: 13 | K14: D | L14: BOTANICO | M14: 13 | N14: M | P14: 13 | Q14: V | R14: BOCCALON - | S14: 13 | T14: D | U14: PIANCA | V14: 13 | W14: M | X14: ?? - ?? | Y14: 13 | Z14: S | AA14: FONTANAFREDDA | AB14: 13 | AC14: L | AE14: 13 | AF14: G | AH14: 13 | AI14: S
A15: 14 | B15: M | D15: 14 | E15: V | G15: 14 | H15: V | J15: 14 | K15: L | M15: 14 | N15: M | P15: 14 | Q15: S | S15: 14 | T15: L | V15: 14 | W15: G | X15: ?? - ?? | Y15: 14 | Z15: D | AB15: 14 | AC15: M | AE15: 14 | AF15: V | AH15: 14 | AI15: D
A16: 15 | B16: M | D16: 15 | E16: S | G16: 15 | H16: S | J16: 15 | K16: M | M16: 15 | N16: G | P16: 15 | Q16: D | S16: 15 | T16: M | V16: 15 | W16: V | X16: PIANCA | Y16: 15 | Z16: L | AB16: 15 | AC16: M | AE16: 15 | AF16: S | AH16: 15 | AI16: L
A17: 16 | B17: G | D17: 16 | E17: D | F17: QMD | G17: 16 | H17: D | I17: QMD | J17: 16 | K17: M | M17: 16 | N17: V | P17: 16 | Q17: L | S17: 16 | T17: M | U17: da portare station da Villa Varda | V17: 16 | W17: S | X17: PIANCA | Y17: 16 | Z17: M | AB17: 16 | AC17: G | AE17: 16 | AF17: D | AG17: QMD | AH17: 16 | AI17: M
A18: 17 | B18: V | D18: 17 | E18: L | G18: 17 | H18: L | J18: 17 | K18: G | M18: 17 | N18: S | P18: 17 | Q18: M | S18: 17 | T18: G | U18: RITA + CUERTO + BOCCALON CONF | V18: 17 | W18: D | X18: PIANCA | Y18: 17 | Z18: M | AB18: 17 | AC18: V | AE18: 17 | AF18: L | AH18: 17 | AI18: M
A19: 18 | B19: S | D19: 18 | E19: M | G19: 18 | H19: M | J19: 18 | K19: V | M19: 18 | N19: D | O19: FIGHT CLUB | P19: 18 | Q19: M | S19: 18 | T19: V | U19: NEGOZI APERTI - Lorenzo Dolcevita - Campari Soda CONF | V19: 18 | W19: L | Y19: 18 | Z19: G | AB19: 18 | AC19: S | AE19: 18 | AF19: M | AH19: 18 | AI19: G
A20: 19 | B20: D | C20: QMD | D20: 19 | E20: M | G20: 19 | H20: M | J20: 19 | K20: S | L20: QMD - PASQUA ANT | M20: 19 | N20: L | P20: 19 | Q20: G | S20: 19 | T20: S | V20: 19 | W20: M | X20: - | Y20: 19 | Z20: V | AA20: STEREO KIDZ | AB20: 19 | AC20: D | AE20: 19 | AF20: M | AH20: 19 | AI20: V
A21: 20 | B21: L | D21: 20 | E21: G | F21: Comple Mamilla Albert | G21: 20 | H21: G | J21: 20 | K21: D | L21: BOTANICO | M21: 20 | N21: M | P21: 20 | Q21: V | R21: MATTEO B - Monkey CONF 18/23 | S21: 20 | T21: D | V21: 20 | W21: M | Y21: 20 | Z21: S | AB21: 20 | AC21: L | AE21: 20 | AF21: G | AH21: 20 | AI21: S
A22: 21 | B22: M | D22: 21 | E22: V | G22: 21 | H22: V | J22: 21 | K22: L | M22: 21 | N22: M | P22: 21 | Q22: S | S22: 21 | T22: L | V22: 21 | W22: G | Y22: 21 | Z22: D | AA22: BOTANICO | AB22: 21 | AC22: M | AE22: 21 | AF22: V | AH22: 21 | AI22: D
A23: 22 | B23: M | D23: 22 | E23: S | G23: 22 | H23: S | J23: 22 | K23: M | M23: 22 | N23: G | P23: 22 | Q23: D | S23: 22 | T23: M | V23: 22 | W23: V | X23: STEREO KIDZ - | Y23: 22 | Z23: L | AB23: 22 | AC23: M | AE23: 22 | AF23: S | AH23: 22 | AI23: L
A24: 23 | B24: G | D24: 23 | E24: D | G24: 23 | H24: D | I24: BOTANICO | J24: 23 | K24: M | M24: 23 | N24: V | O24: Borgo delle Rose | P24: 23 | Q24: L | S24: 23 | T24: M | V24: 23 | W24: S | Y24: 23 | Z24: M | AB24: 23 | AC24: G | AE24: 23 | AF24: D | AH24: 23 | AI24: M
A25: 24 | B25: V | D25: 24 | E25: L | G25: 24 | H25: L | J25: 24 | K25: G | L25: Sagra Primaverile | M25: 24 | N25: S | P25: 24 | Q25: M | S25: 24 | T25: G | V25: 24 | W25: D | X25: PIANCA | Y25: 24 | Z25: M | AB25: 24 | AC25: V | AE25: 24 | AF25: L | AH25: 24 | AI25: M
A26: 25 | B26: S | D26: 25 | E26: M | G26: 25 | H26: M | J26: 25 | K26: V | L26: Sagra Primaverile | M26: 25 | N26: D | O26: BOTANICO | P26: 25 | Q26: M | S26: 25 | T26: V | U26: STEREO KIDZ - Roby Marton CONF | V26: 25 | W26: L | Y26: 25 | Z26: G | AB26: 25 | AC26: S | AE26: 25 | AF26: M | AH26: 25 | AI26: G | AJ26: QMD
A27: 26 | B27: D | D27: 26 | E27: M | G27: 26 | H27: M | J27: 26 | K27: S | L27: Sagra Primaverile | M27: 26 | N27: L | P27: 26 | Q27: G | S27: 26 | T27: S | V27: 26 | W27: M | Y27: 26 | Z27: V | AB27: 26 | AC27: D | AD27: QMD | AE27: 26 | AF27: M | AH27: 26 | AI27: V
A28: 27 | B28: L | D28: 27 | E28: G | G28: 27 | H28: G | J28: 27 | K28: D | L28: Sagra Primaverile | M28: 27 | N28: M | P28: 27 | Q28: V | R28: BOCCALON - Palomitas Tour CONF | S28: 27 | T28: D | U28: PIANCA | V28: 27 | W28: M | Y28: 27 | Z28: S | AB28: 27 | AC28: L | AE28: 27 | AF28: G | AH28: 27 | AI28: S
A29: 28 | B29: M | D29: 28 | E29: V | G29: 28 | H29: V | J29: 28 | K29: L | M29: 28 | N29: M | P29: 28 | Q29: S | S29: 28 | T29: L | V29: 28 | W29: G | Y29: 28 | Z29: D | AA29: QMD VV | AB29: 28 | AC29: M | AE29: 28 | AF29: V | AH29: 28 | AI29: D
A30: 29 | B30: M | G30: 29 | H30: S | J30: 29 | K30: M | M30: 29 | N30: G | P30: 29 | Q30: D | S30: 29 | T30: M | V30: 29 | W30: V | X30: BOCCALON - | Y30: 29 | Z30: L | AB30: 29 | AC30: M | AE30: 29 | AF30: S | AH30: 29 | AI30: L
A31: 30 | B31: G | G31: 30 | H31: D | I31: BOTANICO | J31: 30 | K31: M | M31: 30 | N31: V | P31: 30 | Q31: L | S31: 30 | T31: M | V31: 30 | W31: S | Y31: 30 | Z31: M | AB31: 30 | AC31: G | AE31: 30 | AF31: D | AH31: 30 | AI31: M
A32: 31 | B32: V | G32: 31 | H32: L | M32: 31 | N32: S | O32: XTREME AFTERPARTY | S32: 31 | T32: G | V32: 31 | W32: D | AB32: 31 | AC32: V | AH32: 31 | AI32: M
C34: da definire:
C35: Altos Tequila | D35: PR | F35: ok
C36: Malfy | D36: PR | F36: da programmare con fede
C37: Italicus | D37: PR
C38: Jameson | D38: PR
C39: Monkey 47 | D39: PR | F39: ok
C40: Mezcal + Del Maguey | D40: PR
C41: Bumbu | D41: PR | F41: da programmare 4 O 11
...

Sheet STORICO
U2: 2022 | V2: 2021 | W2: 2020 | X2: 2019 | Y2: 2018 | Z2: 2017
C3: 2025 | D3: CORR | E3: 2024 | F3: CORR | G3: 2023 | H3: CORR | I3: 2022 | J3: CORR | K3: 2021 | L3: CORR | M3: 2020 | N3: CORR | O3: 2019 | P3: CORR | Q3: 2018 | R3: CORR | S3: 2017 | T3: CORR | U3: Ø GIORN | V3: Ø GIORN | W3: Ø GIORN | X3: Ø GIORN | Y3: Ø GIORN | Z3: Ø GIORN
B4: GEN | C4: =GEN!G2 -> 56775.75 | D4: =GEN!G3 -> 37792.46 | E4: 74388.29 | F4: 43806.23 | G4: 58341.5 | H4: 32046.44 | I4: 35123.11 | J4: 22774.86 | K4: 7689.37 | L4: 5395.4 | M4: 41419.56 | N4: 24805 | O4: 34774.86 | P4: 21698 | Q4: 37803.1 | R4: 11851.17 | S4: 31463.3 | T4: 15781.28 | U4: =GEN!G6 -> 2365.6563 | V4: 961.17 | W4: 1726.23 | X4: 1337.49 | Y4: 1453.97 | Z4: 1210.13
B5: FEB | C5: =FEB!G2 -> 64368.1 | D5: =FEB!G3 -> 81218.3 | E5: 80342.27 | F5: 46267.4 | G5: 67770.2 | H5: 38654.29 | I5: 66639.1 | J5: 38234.56 | K5: 29078 | L5: 20063.5 | M5: 49441.92 | N5: 26794 | O5: 46702.85 | P5: 24235 | Q5: 37983.6 | R5: 15365.72 | S5: 27455.7 | U5: =FEB!G6 -> 2682.0042 | V5: 1038.5 | W5: 1977.68 | X5: 1945.95 | Y5: 1582.65 | Z5: 1143.99
B6: MAR | C6: =MAR!G2 -> 91689.91 | D6: =MAR!G3 -> 68421.7 | E6: 94515.58 | F6: 60630.58 | G6: 82422.28 | H6: 53195.06 | I6: 68754.25 | J6: 60715.56 | K6: 9101.1 | L6: 5277.7 | M6: 15671.8 | N6: 12003 | O6: 57431.22 | P6: 44633 | Q6: 44047.5 | R6: 18217.39 | S6: 37294.8 | V6: 1300.16 | W6: 2238.83 | X6: 2127.08 | Y6: 1631.39 | Z6: 1381.29
B7: APR | C7: =APR!G2 -> 123264.42 | D7: =APR!G3 -> 82728.03 | E7: 94111.09 | F7: 77250.32 | G7: 119955.05 | H7: 85725.1 | I7: 83800.67 | J7: 48380.88 | K7: 8201 | L7: 2819.11 | M7: 0 | N7: 0 | O7: 60908.13 | P7: 42199 | Q7: 56281.8 | R7: 27940.04 | S7: 43962.7 | V7: 1640.2 | X7: 2436.33 | Y7: 2164.68 | Z7: 1690.87
B8: MAG | C8: =MAG!G2 -> 84317.25 | D8: =MAG!G3 -> 58778.3 | E8: 70115.08 | F8: 48547.6 | G8: 75105.81 | H8: 79178.38 | I8: 65654.32 | J8: 42597.17 | K8: 59860.1 | L8: 27485.1 | M8: 31802.37 | N8: 17428.27 | O8: 56513.7 | P8: 39594 | Q8: 47372.88 | R8: 29122.43 | S8: 26810.6 | V8: 2137.86 | W8: 2271.6 | X8: 2173.6 | Y8: 1822.03 | Z8: 1165.68
B9: GIU | C9: =GIU!G2 -> 85082.1 | D9: =GIU!G3 -> 71892.4 | E9: 80774.2 | F9: 58069.35 | G9: 85039.1 | H9: 76259.14 | I9: 77460.75 | J9: 50929.8 | K9: 95294.55 | L9: 55977.52 | M9: 69980.7 | N9: 34304 | O9: 64111 | P9: 41427 | Q9: 50407.72 | R9: 39423.41 | S9: 47644.9 | V9: 3176.49 | W9: 2332.69 | X9: 2465.81 | Y9: 1938.76 | Z9: 1642.93
B10: LUG | C10: =LUG!G2 -> 80065.61 | D10: =LUG!G3 -> 54795.1 | E10: 73033.32 | F10: 46247.95 | G10: 74229.9 | H10: 51063.13 | I10: 75429.05 | J10: 46048.1 | K10: 85555.5 | L10: 53653.51 | M10: 65579.86 | N10: 35959 | O10: 63509.15 | P10: 41470 | Q10: 44804.7 | R10: 44073.02 | S10: 36820.8 | V10: 2759.85 | W10: 2115.48 | X10: 2442.66 | Y10: 1723.26 | Z10: 1187.77
B11: AGO | C11: =AGO!G2 -> 95524.9 | D11: =AGO!G3 -> 59157 | E11: 86831.6 | F11: 50117.94 | G11: 81606.73 | H11: 50523.2 | I11: 76063.72 | J11: 62869.05 | K11: 83190.6 | L11: 50158.17 | M11: 71550.95 | N11: 41278 | O11: 66045.21 | P11: 45145 | Q11: 53161.44 | R11: 37363.87 | S11: 39244.59 | V11: 2683.57 | W11: 2308.1 | X11: 2446.12 | Y11: 1968.94 | Z11: 1569.78
B12: SET | C12: =SET!G2 -> 78508.45 | D12: =SET!G3 -> 50010.45 | E12: 72523.28 | F12: 52947 | G12: 99296.93 | H12: 57247.69 | I12: 82270.32 | J12: 53348.14 | K12: 74913.8 | L12: 51542.32 | M12: 77231.6 | N12: 44384 | O12: 69739.17 | P12: 42315 | Q12: 47127.36 | R12: 34086.81 | S12: 34004.9 | V12: 2675.49 | W12: 2574.39 | X12: 2789.57 | Y12: 1812.59 | Z12: 1307.88
B13: OTT | C13: =OTT!G2 -> 82941.89 | D13: =OTT!G3 -> 54187.3 | E13: 74636.9 | F13: 45644.12 | G13: 95037.63 | H13: 51834.59 | I13: 103772.05 | J13: 61993.59 | K13: 65990.45 | L13: 42917.02 | M13: 50047.05 | N13: 41788 | O13: 63533.91 | P13: 40705 | Q13: 45215.5 | R13: 25101.27 | S13: 32335.9 | V13: 2444.09 | W13: 1725.76 | X13: 2353.11 | Y13: 1739.06 | Z13: 1243.69
B14: NOV | C14: =NOV!G2 -> 81065.155 | D14: =NOV!G3 -> 45356.56 | E14: 74908.88 | F14: 50189.3 | G14: 59552 | H14: 41100.7 | I14: 62781.85 | J14: 41722.92 | K14: 59658.74 | L14: 38602.54 | M14: 13459.53 | N14: 12420 | O14: 48248.35 | P14: 30546 | Q14: 41491.1 | R14: 20679.81 | S14: 30615 | V14: 2386.35 | W14: 1121.63 | X14: 1855.71 | Y14: 1595.81 | Z14: 1177.5
B15: DIC | C15: =DIC!G2 -> 89525.485 | D15: =DIC!G3 -> 49855.89 | E15: =54703.41+(94697.5/2) -> 102052.16 | F15: =29236.7+21622.98 -> 50859.68 | G15: 130936.36 | H15: 61907.81 | I15: 84062.8 | J15: 42329.99 | K15: 45808.2 | L15: 30303.38 | M15: 17082.55 | N15: 22793 | O15: 53587.9 | P15: 39223 | Q15: 54891.5 | R15: 15275.1 | S15: 32824.5 | V15: 1579.59 | W15: 1004.86 | X15: 1984.74 | Y15: 2033.02 | Z15: 1262.48
B18: TOT | C18: =SUM(C4:C15) -> 1013129 | D18: =SUM(D4:D15) -> 714193.49 | E18: =SUM(E4:E15) -> 978232.65 | F18: =SUM(F4:F15) -> 630577.47 | G18: =SUM(G4:G15) -> 1029293.5 | H18: =SUM(H4:H15) -> 678735.53 | I18: =SUM(I4:I15) -> 881811.99 | J18: =SUM(J4:J15) -> 571944.62 | ... O18: =SUM(O4:O15) -> 685105.45 | P18: 453194 | Q18: =SUM(Q4:Q15) -> 560588.2 | R18: =SUM(R4:R15) -> 318500.04 | S18: =SUM(S4:S15) -> 420477.69 | U18: - | V18: - | W18: - | X18: - | Y18: - | Z18: -
B19: Ø | C19: =AVERAGE(C4:C15) -> 84427.418 | D19: =D18/C18 -> 0.70493834 | E19: =AVERAGE(E4:E15) -> 81519.388 | F19: =F18/E18 -> 0.6446089 | G19: =AVERAGE(G4:G15) -> 85774.458 | H19: =H18/G18 -> 0.65941885 | I19: =AVERAGE(I4:I15) -> 73484.333 | J19: =J18/I18 -> 0.64860155 | K19: =AVERAGE(K4:K15) -> 52028.451 | L19: =L18/K18 -> 0.61536086 | M19: =AVERAGE(M4:M15) -> 41938.991 | N19: =N18/M18 -> 0.62383529 | O19: =AVERAGE(O4:O11) -> 56249.515 | P19: =P18/O18 -> 0.66149525 | Q19: =Q18/12 -> 46715.683 | R19: =R18/Q18 -> 0.56815331 | S19: =S18/12 -> 35039.808 | U19: =AVERAGE(U4:U13) -> 2523.8302 | V19: =AVERAGE(V4:V13) -> 2081.738 | W19: =M18/249 -> 2021.1562 | X19: =O18/312 -> 2195.8508 | Y19: =AVERAGE(Y4:Y12) -> 1788.6967 | Z19: =AVERAGE(Z4:Z12) -> 1366.7022
B21: MATTINA
C22: 2025 | D22: Ø 2025 | E22: 2024 | F22: Ø 2024 | G22: 2023 | H22: Ø 2023 | I22: 2022 | J22: Ø 2022 | K22: 2021 | L22: Ø 2021 | M22: 2020 | N22: Ø 2020 | O22: 2019 | P22: Ø 2019
B23: GEN | C23: =SUM(GEN!D10:E40) -> 7723.1 | D23: =C23/COUNT(GEN!D10:D40) -> 321.79583 | E23: 5970.1 | F23: 259.57 | G23: 6005 | H23: 261.09 | I23: 3670 | J23: 262 | K23: 0 | L23: 0 | M23: 6400 | N23: 267 | O23: 7640 | P23: 294
B24: FEB | C24: =SUM(FEB!D10:E40) -> 7935.95 | D24: =C24/COUNT(FEB!D10:D40) -> 330.66458 | E24: 7761.8 | F24: 323.41 | G24: 6802 | H24: 283.42 | I24: 6310.5 | J24: 263 | K24: 9900 | L24: 350 | M24: 8000 | N24: 320 | O24: 8214 | P24: 340
B25: MAR | C25: =SUM(MAR!D10:E40) -> 10716.4 | D25: =C25/COUNT(MAR!D10:D40) -> 412.16923 | E25: 8997.1 | F25: 333.23 | G25: 11082 | H25: 410.44 | I25: 8373 | J25: 349 | K25: 0 | L25: 0 | M25: 1960 | N25: 280 | O25: 11920 | P25: 440
B26: APR | C26: =SUM(APR!D10:E40) -> 12982.5 | D26: =C26/COUNT(APR!D10:D40) -> 499.32692 | E26: 11727.1 | F26: 469.08 | G26: 13939.8 | H26: 536.15 | I26: 10957 | J26: 438 | K26: 0 | L26: 0 | M26: 0 | N26: 0 | O26: 13013 | P26: 507
B27: MAG | C27: =SUM(MAG!D10:E40) -> 15039.65 | D27: =C27/COUNT(MAG!D10:D40) -> 557.02407 | E27: 11607.5 | F27: 429.91 | G27: 10896 | H27: 419.08 | I27: 9900 | J27: 380 | K27: 14800 | L27: 530 | M27: 4400 | N27: 340 | O27: 10500 | P27: 403
B28: GIU | C28: =SUM(GIU!D10:E40) -> 11841.2 | D28: =C28/COUNT(GIU!D10:D40) -> 473.648 | E28: 11146.7 | F28: =E28/26 -> 428.71923 | G28: 11313.4 | H28: 435.13 | I28: 10320 | J28: 415 | K28: 12409 | L28: 413 | M28: 11100 | N28: 370 | O28: 12000 | P28: 431
B29: LUG | C29: =SUM(LUG!D10:E40) -> 10183 | D29: =C29/COUNT(LUG!D10:D40) -> 391.65385 | E29: 8973.73 | F29: 345.14 | G29: 9430 | H29: 349.26 | I29: 8130 | J29: 325 | K29: 9630 | L29: 310 | M29: 10700 | N29: 345 | O29: 11600 | P29: 446
B30: AGO | C30: =SUM(AGO!D10:E40) -> 12403 | D30: =C30/COUNT(AGO!D10:D40) -> 477.03846 | E30: 10625.2 | F30: 408.66 | G30: 10860.6 | H30: =AGO!N2 -> 496.12 | I30: 10900 | J30: 420 | K30: 11160 | L30: 360 | M30: 13580 | N30: 440 | O30: 12900 | P30: 480
B31: SET | C31: =SUM(SET!D10:E39) -> 11650.1 | D31: =C31/COUNT(SET!D10:D39) -> 485.42083 | E31: 10972.85 | F31: 457.2 | G31: 12701 | H31: 423.37 | I31: 12630 | J31: 485 | K31: 10750 | L31: 380 | M31: 12570 | N31: 419 | O31: 12900 | P31: 520
B32: OTT | C32: =SUM(OTT!D10:E40) -> 9305.35 | D32: =C32/COUNT(OTT!D10:D40) -> 344.64259 | E32: 8637.09 | F32: =E32/27 -> 319.89222 | G32: 10326.9 | H32: 397.19 | I32: 12030 | J32: 445 | K32: 10305 | L32: 380 | M32: 12900 | N32: 398 | O32: 9965 | P32: 370
B33: NOV | C33: =SUM(NOV!D10:E40) -> 8381.38 | D33: =C33/COUNT(NOV!D10:D40) -> 322.36077 | E33: 10351.71 | F33: =E33/26 -> 398.14269 | G33: 7436.4 | H33: 338.02 | I33: 8020 | J33: 320 | K33: 6404 | L33: 260 | M33: 0 | N33: 0 | O33: 7158 | P33: 275
B34: DIC | C34: =SUM(DIC!D10:E40) -> 5758.11 | E34: 7404.99 | F34: 308.54 | G34: 7006 | H34: =G34/25 -> 280.24 | I34: 6690 | J34: 278 | K34: 4728 | L34: 160 | M34: 0 | N34: 0 | O34: 7139 | P34: 265
C35: =SUM(C23:C34) -> 123919.74 | D35: =AVERAGE(D23:D34) -> 419.6132 | E35: =SUM(E23:E34) -> 114175.87 | F35: =AVERAGE(F23:F34) -> 373.45785 | G35: =SUM(G23:G34) -> 117799.1 | H35: =AVERAGE(H23:H34) -> 385.7925 | I35: =SUM(I23:I34) -> 107930.5 | J35: =AVERAGE(J23:J34) -> 365 | K35: =SUM(K23:K34) -> 90086 | L35: =SUM(L23:L34)/9 -> 349.22222 | M35: =SUM(M23:M34) -> 81610 | N35: =SUM(N23:N34)/9 -> 353.22222 | O35: =SUM(O23:O34) -> 124949 | P35: =AVERAGE(P23:P34) -> 397.58333

Sheet BUDGET 25
D2: 45658 | F2: 45689 | H2: 45717 | J2: 45748 | L2: 45778 | N2: 45809 | P2: 45839 | R2: 45870 | T2: 45901 | V2: 45931 | X2: 45962 | Z2: 45992 | AB2: TOTALE
B3: UTILE | D3: =D5+D6-D17 -> #N/A | E3: =D3/$AB$3 -> #N/A | F3: =F5+F6-F17 -> #N/A | G3: =F3/$AB$3 -> #N/A | H3: =H5+H6-H17 -> #N/A | I3: =H3/$AB$3 -> #N/A | J3: =J5+J6-J17 -> #N/A | K3: =J3/$AB$3 -> #N/A | L3: =L5+L6-L17 -> #N/A | M3: =L3/$AB$3 -> #N/A | N3: =N5+N6-N17 -> #N/A | O3: =N3/$AB$3 -> #N/A | P3: =P5+P6-P17 -> #N/A | Q3: =P3/$AB$3 -> #N/A | R3: =R5+R6-R17 -> #N/A | S3: =R3/$AB$3 -> #N/A | T3: =T5+T6-T17 -> #N/A | U3: =T3/$AB$3 -> #N/A | V3: =V5+V6-V17 -> #N/A | W3: =V3/$AB$3 -> #N/A | X3: =X5+X6-X17 -> #N/A | Y3: =X3/$AB$3 -> #N/A | Z3: =Z5+Z6-Z17 -> #N/A | AA3: =Z3/$AB$3 -> #N/A | AB3: =Z3+X3+V3+T3+R3+P3+N3+L3+J3+H3+F3+D3 -> #N/A
B4: BUDGET | D4: 60000 | F4: 60000 | H4: 75000 | J4: 90000 | L4: 65000 | N4: 75000 | P4: 70000 | R4: 75000 | T4: 80000 | V4: 80000 | X4: 60000 | Z4: 80000 | AB4: =Z4+X4+V4+T4+R4+P4+N4+L4+J4+H4+F4+D4 -> 870000
B5: RICAVI | D5: =SUMIFS(CASSA!$E:$E,CASSA!$B:$B,">=01/01/2025",CASSA!$B:$B,"<=31/01/2025",CASSA!$G:$G,"Corrispettivi")+SUMIFS(CASSA!$E:$E,CASSA!$B:$B,">=01/01/2025",CASSA!$B:$B,"<=31/01/2025",CASSA!$G:$G,"Ricavi EVENTI")+ SUMIFS(CASSA!$E:$E,CASSA!$B:$B,">=01/01/2025",CASSA!$B:$B,"<=31/01/2025",CASSA!$G:$G,"Proventi vari")+SUMIFS(BANCA!$E:$E,BANCA!$B:$B,">=01/01/2025",BANCA!$B:$B,"<=31/01/2025",BANCA!$G:$G,"Corrispettivi")+ SUMIFS(BANCA!$E:$E,BANCA!$B:$B,">=01/01/2025",BANCA!$B:$B,"<=31/01/2025",BANCA!$G:$G,"Ricavi EVENTI")+ SUMIFS(BANCA!$E:$E,BANCA!$B:$B,">=01/01/2025",BANCA!$B:$B,"<=31/01/2025",BANCA!$G:$G,"Proventi vari") -> 64790.96 | E5: =D5/$AB$5 -> 0.088261236 | F5: =SUMIFS(CASSA!$E:$E,CASSA!$B:$B,">=01/02/2025",CASSA!$B:$B,"<=28/02/2025",CASSA!$G:$G,"Corrispettivi")+SUMIFS(CASSA!$E:$E,CASSA!$B:$B,">=01/02/2025",CASSA!$B:$B,"<=28/02/2025",CASSA!$G:$G,"Ricavi EVENTI")+ SUMIFS(CASSA!$E:$E,CASSA!$B:$B,">=01/02/2025",CASSA!$B:$B,"<=28/02/2025",CASSA!$G:$G,"Proventi vari")+ SUMIFS(BANCA!$E:$E,BANCA!$B:$B,">=01/02/2025",BANCA!$B:$B,"<=28/02/2025",BANCA!$G:$G,"Corrispettivi")+ SUMIFS(BANCA!$E:$E,BANCA!$B:$B,">=01/02/2025",BANCA!$B:$B,"<=28/02/2025",BANCA!$G:$G,"Ricavi EVENTI")+ SUMIFS(BANCA!$E:$E,BANCA!$B:$B,">=01/02/2025",BANCA!$B:$B,"<=28/02/2025",BANCA!$G:$G,"Proventi vari") -> 46592.57 | G5: =F5/$AB$5 -> 0.063470549 | H5: =SUMIFS(CASSA!$E:$E,CASSA!$B:$B,">=01/03/2025",CASSA!$B:$B,"<=31/03/2025",CASSA!$G:$G,"Corrispettivi")+SUMIFS(CASSA!$E:$E,CASSA!$B:$B,">=01/03/2025",CASSA!$B:$B,"<=31/03/2025",CASSA!$G:$G,"Ricavi EVENTI")+ SUMIFS(CASSA!$E:$E,CASSA!$B:$B,">=01/03/2025",CASSA!$B:$B,"<=31/03/2025",CASSA!$G:$G,"Proventi vari")+SUMIFS(BANCA!$E:$E,BANCA!$B:$B,">=01/03/2025",BANCA!$B:$B,"<=31/03/2025",BANCA!$G:$G,"Corrispettivi")+ SUMIFS(BANCA!$E:$E,BANCA!$B:$B,">=01/03/2025",BANCA!$B:$B,"<=31/03/2025",BANCA!$G:$G,"Ricavi EVENTI")+ SUMIFS(BANCA!$E:$E,BANCA!$B:$B,">=01/03/2025",BANCA!$B:$B,"<=31/03/2025",BANCA!$G:$G,"Proventi vari") -> 49190.07 | I5: =H5/$AB$5 -> 0.067008984 | J5: =SUMIFS(CASSA!$E:$E,CASSA!$B:$B,">=01/04/2025",CASSA!$B:$B,"<=30/04/2025",CASSA!$G:$G,"Corrispettivi")+SUMIFS(CASSA!$E:$E,CASSA!$B:$B,">=01/04/2025",CASSA!$B:$B,"<=30/04/2025",CASSA!$G:$G,"Ricavi EVENTI")+ SUMIFS(CASSA!$E:$E,CASSA!$B:$B,">=01/04/2025",CASSA!$B:$B,"<=30/04/2025",CASSA!$G:$G,"Proventi vari")+SUMIFS(BANCA!$E:$E,BANCA!$B:$B,">=01/04/2025",BANCA!$B:$B,"<=30/04/2025",BANCA!$G:$G,"Corrispettivi")+ SUMIFS(BANCA!$E:$E,BANCA!$B:$B,">=01/04/2025",BANCA!$B:$B,"<=30/04/2025",BANCA!$G:$G,"Ricavi EVENTI")+ SUMIFS(BANCA!$E:$E,BANCA!$B:$B,">=01/04/2025",BANCA!$B:$B,"<=30/04/2025",BANCA!$G:$G,"Proventi vari") -> 57246.56 | K5: =J5/$AB$5 -> 0.077983906 | L5: =SUMIFS(CASSA!$E:$E,CASSA!$B:$B,">=01/05/2025",CASSA!$B:$B,"<=31/05/2025",CASSA!$G:$G,"Corrispettivi")+SUMIFS(CASSA!$E:$E,CASSA!$B:$B,">=01/05/2025",CASSA!$B:$B,"<=31/05/2025",CASSA!$G:$G,"Ricavi EVENTI")+ SUMIFS(CASSA!$E:$E,CASSA!$B:$B,">=01/05/2025",CASSA!$B:$B,"<=31/05/2025",CASSA!$G:$G,"Proventi vari")+SUMIFS(BANCA!$E:$E,BANCA!$B:$B,">=01/05/2025",BANCA!$B:$B,"<=31/05/2025",BANCA!$G:$G,"Corrispettivi")+ SUMIFS(BANCA!$E:$E,BANCA!$B:$B,">=01/05/2025",BANCA!$B:$B,"<=31/05/2025",BANCA!$G:$G,"Ricavi EVENTI")+ SUMIFS(BANCA!$E:$E,BANCA!$B:$B,">=01/05/2025",BANCA!$B:$B,"<=31/05/2025",BANCA!$G:$G,"Proventi vari") -> 36801.7 | M5: =L5/$AB$5 -> 0.050132974 | N5: =SUMIFS(CASSA!$E:$E,CASSA!$B:$B,">=01/06/2025",CASSA!$B:$B,"<=30/06/2025",CASSA!$G:$G,"Corrispettivi")+SUMIFS(CASSA!$E:$E,CASSA!$B:$B,">=01/06/2025",CASSA!$B:$B,"<=30/06/2025",CASSA!$G:$G,"Ricavi EVENTI")+ SUMIFS(CASSA!$E:$E,CASSA!$B:$B,">=01/06/2025",CASSA!$B:$B,"<=30/06/2025",CASSA!$G:$G,"Proventi vari")+SUMIFS(BANCA!$E:$E,BANCA!$B:$B,">=01/06/2025",BANCA!$B:$B,"<=30/06/2025",BANCA!$G:$G,"Corrispettivi")+ SUMIFS(BANCA!$E:$E,BANCA!$B:$B,">=01/06/2025",BANCA!$B:$B,"<=30/06/2025",BANCA!$G:$G,"Ricavi EVENTI")+ SUMIFS(BANCA!$E:$E,BANCA!$B:$B,">=01/06/2025",BANCA!$B:$B,"<=30/06/2025",BANCA!$G:$G,"Proventi vari") -> 73885.72 | O5: =N5/$AB$5 -> 0.10065054 | P5: =SUMIFS(CASSA!$E:$E,CASSA!$B:$B,">=01/07/2025",CASSA!$B:$B,"<=31/07/2025",CASSA!$G:$G,"Corrispettivi")+SUMIFS(CASSA!$E:$E,CASSA!$B:$B,">=01/07/2025",CASSA!$B:$B,"<=31/07/2025",CASSA!$G:$G,"Ricavi EVENTI")+ SUMIFS(CASSA!$E:$E,CASSA!$B:$B,">=01/07/2025",CASSA!$B:$B,"<=31/07/2025",CASSA!$G:$G,"Proventi vari")+SUMIFS(BANCA!$E:$E,BANCA!$B:$B,">=01/07/2025",BANCA!$B:$B,"<=31/07/2025",BANCA!$G:$G,"Corrispettivi")+ SUMIFS(BANCA!$E:$E,BANCA!$B:$B,">=01/07/2025",BANCA!$B:$B,"<=31/07/2025",BANCA!$G:$G,"Ricavi EVENTI")+ SUMIFS(BANCA!$E:$E,BANCA!$B:$B,">=01/07/2025",BANCA!$B:$B,"<=31/07/2025",BANCA!$G:$G,"Proventi vari") -> 75739.53 | Q5: =P5/$AB$5 -> 0.10317588 | R5: =SUMIFS(CASSA!$E:$E,CASSA!$B:$B,">=01/08/2025",CASSA!$B:$B,"<=31/08/2025",CASSA!$G:$G,"Corrispettivi")+SUMIFS(CASSA!$E:$E,CASSA!$B:$B,">=01/08/2025",CASSA!$B:$B,"<=31/08/2025",CASSA!$G:$G,"Ricavi EVENTI")+ SUMIFS(CASSA!$E:$E,CASSA!$B:$B,">=01/08/2025",CASSA!$B:$B,"<=31/08/2025",CASSA!$G:$G,"Proventi vari")+SUMIFS(BANCA!$E:$E,BANCA!$B:$B,">=01/08/2025",BANCA!$B:$B,"<=31/08/2025",BANCA!$G:$G,"Corrispettivi")+ SUMIFS(BANCA!$E:$E,BANCA!$B:$B,">=01/08/2025",BANCA!$B:$B,"<=31/08/2025",BANCA!$G:$G,"Ricavi EVENTI")+ SUMIFS(BANCA!$E:$E,BANCA!$B:$B,">=01/08/2025",BANCA!$B:$B,"<=31/08/2025",BANCA!$G:$G,"Proventi vari") -> 89177.18 | S5: =R5/$AB$5 -> 0.12148127 | T5: =SUMIFS(CASSA!$E:$E,CASSA!$B:$B,">=01/09/2025",CASSA!$B:$B,"<=30/09/2025",CASSA!$G:$G,"Corrispettivi")+SUMIFS(CASSA!$E:$E,CASSA!$B:$B,">=01/09/2025",CASSA!$B:$B,"<=30/09/2025",CASSA!$G:$G,"Ricavi EVENTI")+ SUMIFS(CASSA!$E:$E,CASSA!$B:$B,">=01/09/2025",CASSA!$B:$B,"<=30/09/2025",CASSA!$G:$G,"Proventi vari")+SUMIFS(BANCA!$E:$E,BANCA!$B:$B,">=01/09/2025",BANCA!$B:$B,"<=30/09/2025",BANCA!$G:$G,"Corrispettivi")+ SUMIFS(BANCA!$E:$E,BANCA!$B:$B,">=01/09/2025",BANCA!$B:$B,"<=30/09/2025",BANCA!$G:$G,"Ricavi EVENTI")+ SUMIFS(BANCA!$E:$E,BANCA!$B:$B,">=01/09/2025",BANCA!$B:$B,"<=30/09/2025",BANCA!$G:$G,"Proventi vari") -> 83108.22 | U5: =T5/$AB$5 -> 0.11321385 | V5: =SUMIFS(CASSA!$E:$E,CASSA!$B:$B,">=01/10/2025",CASSA!$B:$B,"<=31/10/2025",CASSA!$G:$G,"Corrispettivi")+SUMIFS(CASSA!$E:$E,CASSA!$B:$B,">=01/10/2025",CASSA!$B:$B,"<=31/10/2025",CASSA!$G:$G,"Ricavi EVENTI")+ SUMIFS(CASSA!$E:$E,CASSA!$B:$B,">=01/10/2025",CASSA!$B:$B,"<=31/10/2025",CASSA!$G:$G,"Proventi vari")+SUMIFS(BANCA!$E:$E,BANCA!$B:$B,">=01/10/2025",BANCA!$B:$B,"<=31/10/2025",BANCA!$G:$G,"Corrispettivi")+ SUMIFS(BANCA!$E:$E,BANCA!$B:$B,">=01/10/2025",BANCA!$B:$B,"<=31/10/2025",BANCA!$G:$G,"Ricavi EVENTI")+ SUMIFS(BANCA!$E:$E,BANCA!$B:$B,">=01/10/2025",BANCA!$B:$B,"<=31/10/2025",BANCA!$G:$G,"Proventi vari") -> 64821.71 | W5: =V5/$AB$5 -> 0.088303125 | X5: =SUMIFS(CASSA!$E:$E,CASSA!$B:$B,">=01/11/2025",CASSA!$B:$B,"<=30/11/2025",CASSA!$G:$G,"Corrispettivi")+SUMIFS(CASSA!$E:$E,CASSA!$B:$B,">=01/11/2025",CASSA!$B:$B,"<=30/11/2025",CASSA!$G:$G,"Ricavi EVENTI")+ SUMIFS(CASSA!$E:$E,CASSA!$B:$B,">=01/11/2025",CASSA!$B:$B,"<=30/11/2025",CASSA!$G:$G,"Proventi vari")+SUMIFS(BANCA!$E:$E,BANCA!$B:$B,">=01/11/2025",BANCA!$B:$B,"<=30/11/2025",BANCA!$G:$G,"Corrispettivi")+ SUMIFS(BANCA!$E:$E,BANCA!$B:$B,">=01/11/2025",BANCA!$B:$B,"<=30/11/2025",BANCA!$G:$G,"Ricavi EVENTI")+ SUMIFS(BANCA!$E:$E,BANCA!$B:$B,">=01/11/2025",BANCA!$B:$B,"<=30/11/2025",BANCA!$G:$G,"Proventi vari") -> 56754.75 | Y5: =X5/$AB$5 -> 0.07731394 | Z5: =SUMIFS(CASSA!$E:$E,CASSA!$B:$B,">=01/12/2025",CASSA!$B:$B,"<=31/12/2025",CASSA!$G:$G,"Corrispettivi")+SUMIFS(CASSA!$E:$E,CASSA!$B:$B,">=01/12/2025",CASSA!$B:$B,"<=31/12/2025",CASSA!$G:$G,"Ricavi EVENTI")+ SUMIFS(CASSA!$E:$E,CASSA!$B:$B,">=01/12/2025",CASSA!$B:$B,"<=31/12/2025",CASSA!$G:$G,"Proventi vari")+SUMIFS(BANCA!$E:$E,BANCA!$B:$B,">=01/12/2025",BANCA!$B:$B,"<=31/12/2025",BANCA!$G:$G,"Corrispettivi")+ SUMIFS(BANCA!$E:$E,BANCA!$B:$B,">=01/12/2025",BANCA!$B:$B,"<=31/12/2025",BANCA!$G:$G,"Ricavi EVENTI")+ SUMIFS(BANCA!$E:$E,BANCA!$B:$B,">=01/12/2025",BANCA!$B:$B,"<=31/12/2025",BANCA!$G:$G,"Proventi vari") -> 35972.75 | AA5: =Z5/$AB$5 -> 0.04900374 | AB5: =Z5+X5+V5+T5+R5+P5+N5+L5+J5+H5+F5+D5 -> 734081.72
B6: COSTI | D6: =-SUM(D12:D16) -> -43358.54 | E6: =D6/$AB$6 -> 0.059281281 | F6: =-SUM(F12:F16) -> -44435.15 | G6: =F6/$AB$6 -> 0.060753259 | H6: =-SUM(H12:H16) -> -68202.78 | I6: =H6/$AB$6 -> 0.093249177 | J6: =-SUM(J12:J16) -> -69003.2 | K6: =J6/$AB$6 -> 0.094343539 | L6: =-SUM(L12:L16) -> -61315.09 | M6: =L6/$AB$6 -> 0.083832091 | N6: =-SUM(N12:N16) -> -70034.13 | O6: =N6/$AB$6 -> 0.095753061 | P6: =-SUM(P12:P16) -> -78963.79 | Q6: =P6/$AB$6 -> 0.107962 | R6: =-SUM(R12:R16) -> -70800.7 | S6: =R6/$AB$6 -> 0.096801142 | T6: =-SUM(T12:T16) -> -70436.91 | U6: =T6/$AB$6 -> 0.096303756 | V6: =-SUM(V12:V16) -> -67969.7 | W6: =V6/$AB$6 -> 0.092930502 | X6: =-SUM(X12:X16) -> -64041.13 | Y6: =X6/$AB$6 -> 0.087559227 | Z6: =-SUM(Z12:Z16) -> -22842.44 | AA6: =Z6/$AB$6 -> 0.031230966 | AB6: =Z6+X6+V6+T6+R6+P6+N6+L6+J6+H6+F6+D6 -> -731403.56
B7: CASH FLOW OPERATIVO | D7: =D5+D6-D17 -> #N/A | E7: =D7/$AB$7 -> #N/A | F7: =F5+F6-F17 -> #N/A | G7: =F7/$AB$7 -> #N/A | H7: =H5+H6-H17 -> #N/A | I7: =H7/$AB$7 -> #N/A | J7: =J5+J6-J17 -> #N/A | K7: =J7/$AB$7 -> #N/A | L7: =L5+L6-L17 -> #N/A | M7: =L7/$AB$7 -> #N/A | N7: =N5+N6-N17 -> #N/A | O7: =N7/$AB$7 -> #N/A | P7: =P5+P6-P17 -> #N/A | Q7: =P7/$AB$7 -> #N/A | R7: =R5+R6-R17 -> #N/A | S7: =R7/$AB$7 -> #N/A | T7: =T5+T6-T17 -> #N/A | U7: =T7/$AB$7 -> #N/A | V7: =V5+V6-V17 -> #N/A | W7: =V7/$AB$7 -> #N/A | X7: =X5+X6-X17 -> #N/A | Y7: =X7/$AB$7 -> #N/A | Z7: =Z5+Z6-Z17 -> #N/A | AA7: =Z7/$AB$7 -> #N/A | AB7: =Z7+X7+V7+T7+R7+P7+N7+L7+J7+H7+F7+D7 -> #N/A
B8: FREE CASH FLOW | D8: =D5+D6-D17-D20-D19-D18+D21 -> #N/A | F8: =F5+F6-F17-F20-F19-F18+F21 -> #N/A | H8: =H5+H6-H17-H20-H19-H18+H21 -> #N/A | J8: =J5+J6-J17-J20-J19-J18+J21 -> #N/A | L8: =L5+L6-L17-L20-L19-L18+L21 -> #N/A | N8: =N5+N6-N17-N20-N19-N18+N21 -> #N/A | P8: =P5+P6-P17-P20-P19-P18+P21 -> #N/A | R8: =R5+R6-R17-R20-R19-R18+R21 -> #N/A | T8: =T5+T6-T17-T20-T19-T18+T21 -> #N/A | V8: =V5+V6-V17-V20-V19-V18+V21 -> #N/A | X8: =X5+X6-X17-X20-X19-X18+X21 -> #N/A | Z8: =Z5+Z6-Z17-Z20-Z19-Z18+Z21 -> #N/A | AB8: =Z8+X8+V8+T8+R8+P8+N8+L8+J8+H8+F8+D8 -> #N/A
B9: LIQUIDITÀ | D9: =CASSA!$D$3+BANCA!$D$3 -> 117783.43 | F9: =_xlfn.XLOOKUP(EOMONTH(IF(ISNUMBER(D$2), D$2, DATEVALUE("1 "&D$2&" 2025")), 0),#REF!,#REF!) -> #REF! | H9: =_xlfn.XLOOKUP(EOMONTH(IF(ISNUMBER(F$2), F$2, DATEVALUE("1 "&F$2&" 2025")), 0),#REF!,#REF!) -> #REF! | J9: =_xlfn.XLOOKUP(EOMONTH(IF(ISNUMBER(H$2), H$2, DATEVALUE("1 "&H$2&" 2025")), 0),#REF!,#REF!) -> #REF! | L9: =_xlfn.XLOOKUP(EOMONTH(IF(ISNUMBER(J$2), J$2, DATEVALUE("1 "&J$2&" 2025")), 0),#REF!,#REF!) -> #REF! | N9: =_xlfn.XLOOKUP(EOMONTH(IF(ISNUMBER(L$2), L$2, DATEVALUE("1 "&L$2&" 2025")), 0),#REF!,#REF!) -> #REF! | P9: =_xlfn.XLOOKUP(EOMONTH(IF(ISNUMBER(N$2), N$2, DATEVALUE("1 "&N$2&" 2025")), 0),#REF!,#REF!) -> #REF! | R9: =_xlfn.XLOOKUP(EOMONTH(IF(ISNUMBER(P$2), P$2, DATEVALUE("1 "&P$2&" 2025")), 0),#REF!,#REF!) -> #REF! | T9: =_xlfn.XLOOKUP(EOMONTH(IF(ISNUMBER(R$2), R$2, DATEVALUE("1 "&R$2&" 2025")), 0),#REF!,#REF!) -> #REF! | V9: =_xlfn.XLOOKUP(EOMONTH(IF(ISNUMBER(T$2), T$2, DATEVALUE("1 "&T$2&" 2025")), 0),#REF!,#REF!) -> #REF! | X9: =_xlfn.XLOOKUP(EOMONTH(IF(ISNUMBER(V$2), V$2, DATEVALUE("1 "&V$2&" 2025")), 0),#REF!,#REF!) -> #REF! | Z9: =_xlfn.XLOOKUP(EOMONTH(IF(ISNUMBER(X$2), X$2, DATEVALUE("1 "&X$2&" 2025")), 0),#REF!,#REF!) -> #REF! | AB9: =_xlfn.XLOOKUP(EOMONTH(IF(ISNUMBER(Z$2), Z$2, DATEVALUE("1 "&Z$2&" 2025")), 0),#REF!,#REF!) -> #REF!
B10: LIQUIDITÀ FORMULA
B12: Costo Personale | D12: =SUM(D24:D29) -> 15593.08 | E12: =D12/D$5 -> 0.24066753 | F12: =SUM(F24:F29) -> 13875.64 | G12: =F12/F$5 -> 0.297808 | H12: =SUM(H24:H29) -> 16730.86 | I12: =H12/H$5 -> 0.34012678 | J12: =SUM(J24:J29) -> 19086.24 | K12: =J12/J$5 -> 0.33340414 | L12: =SUM(L24:L29) -> 19645.37 | M12: =L12/L$5 -> 0.53381692 | N12: =SUM(N24:N29) -> 17504.54 | O12: =N12/N$5 -> 0.23691371 | P12: =SUM(P24:P29) -> 21382.35 | Q12: =P12/P$5 -> 0.28231427 | R12: =SUM(R24:R29) -> 26492.03 | S12: =R12/R$5 -> 0.29707185 | T12: =SUM(T24:T29) -> 14544.71 | U12: =T12/T$5 -> 0.17500928 | V12: =SUM(V24:V29) -> 13466 | W12: =V12/V$5 -> 0.20773904 | X12: =SUM(X24:X29) -> 25510.19 | Y12: =X12/X$5 -> 0.44948114 | Z12: =SUM(Z24:Z29) -> 15526.87 | AA12: =Z12/Z$5 -> 0.43162866 | AB12: =Z12+X12+V12+T12+R12+P12+N12+L12+J12+H12+F12+D12 -> 219357.88 | AC12: =AB12/$AB$5 -> 0.29881943
B13: Costi Materie Prime e Sussidiarie | D13: =SUM(D33:D35) -> 13584.66 | E13: =D13/$D$5 -> 0.20966906 | F13: =SUM(F33:F35) -> 15498.15 | G13: =F13/$D$5 -> 0.23920235 | H13: =SUM(H33:H35) -> 30833.83 | I13: =H13/$D$5 -> 0.4758971 | J13: =SUM(J33:J35) -> 31275.95 | K13: =J13/$D$5 -> 0.48272089 | L13: =SUM(L33:L35) -> 24743.09 | M13: =L13/$D$5 -> 0.38189108 | N13: =SUM(N33:N35) -> 32049.49 | O13: =N13/$D$5 -> 0.4946599 | P13: =SUM(P33:P35) -> 40676.3 | Q13: =P13/$D$5 -> 0.62780826 | R13: =SUM(R33:R35) -> 32020.62 | S13: =R13/$D$5 -> 0.49421432 | T13: =SUM(T33:T35) -> 40632.55 | U13: =T13/$D$5 -> 0.62713301 | V13: =SUM(V33:V35) -> 35301.1 | W13: =V13/$D$5 -> 0.54484607 | X13: =SUM(X33:X35) -> 14641.23 | Y13: =X13/$D$5 -> 0.22597643 | Z13: =SUM(Z33:Z35) -> -2710.13 | AA13: =Z13/$D$5 -> -0.041828829 | AB13: =Z13+X13+V13+T13+R13+P13+N13+L13+J13+H13+F13+D13 -> 308546.84 | AC13: =AB13/$AB$5 -> 0.42031675
B14: Costi Amministrativi | D14: =SUM(D38:D41) -> 0 | E14: =D14/$D$5 -> 0 | F14: =SUM(F38:F41) -> 0 | G14: =F14/$D$5 -> 0 | H14: =SUM(H38:H41) -> 0 | I14: =H14/$D$5 -> 0 | J14: =SUM(J38:J41) -> 0 | K14: =J14/$D$5 -> 0 | L14: =SUM(L38:L41) -> 0 | M14: =L14/$D$5 -> 0 | N14: =SUM(N38:N41) -> 1407 | O14: =N14/$D$5 -> 0.021715992 | P14: =SUM(P38:P41) -> 1977.16 | Q14: =P14/$D$5 -> 0.030515986 | R14: =SUM(R38:R41) -> 2652 | S14: =R14/$D$5 -> 0.040931636 | T14: =SUM(T38:T41) -> 1990.85 | U14: =T14/$D$5 -> 0.03072728 | V14: =SUM(V38:V41) -> 1409 | W14: =V14/$D$5 -> 0.021746861 | X14: =SUM(X38:X41) -> 2754 | Y14: =X14/$D$5 -> 0.04250593 | Z14: =SUM(Z38:Z41) -> 0 | AA14: =Z14/$D$5 -> 0 | AB14: =Z14+X14+V14+T14+R14+P14+N14+L14+J14+H14+F14+D14 -> 12190.01 | AC14: =AB14/$AB$5 -> 0.016605794
B15: Godimento beni di terzi | D15: =SUM(D45:D47) -> 7479.51 | E15: =D15/$D$5 -> 0.11544064 | F15: =SUM(F45:F47) -> 5314.95 | G15: =F15/$D$5 -> 0.082032277 | H15: =SUM(H45:H47) -> 7063.7 | I15: =H15/$D$5 -> 0.10902293 | J15: =SUM(J45:J47) -> 5200.69 | K15: =J15/$D$5 -> 0.08026876 | L15: =SUM(L45:L47) -> 3611.7 | M15: =L15/$D$5 -> 0.055743888 | N15: =SUM(N45:N47) -> 8585.6 | O15: =N15/$D$5 -> 0.13251231 | P15: =SUM(P45:P47) -> 4394.29 | Q15: =P15/$D$5 -> 0.067822579 | R15: =SUM(R45:R47) -> 4121.5 | S15: =R15/$D$5 -> 0.063612269 | T15: =SUM(T45:T47) -> 4202.2 | U15: =T15/$D$5 -> 0.064857813 | V15: =SUM(V45:V47) -> 3815.67 | W15: =V15/$D$5 -> 0.058892012 | X15: =SUM(X45:X47) -> 8663.6 | Y15: =X15/$D$5 -> 0.13371619 | Z15: =SUM(Z45:Z47) -> 4116.6 | AA15: =Z15/$D$5 -> 0.063536642 | AB15: =Z15+X15+V15+T15+R15+P15+N15+L15+J15+H15+F15+D15 -> 66570.01 | AC15: =AB15/$AB$5 -> 0.09068474
B16: Costi per Servizi | D16: =SUM(D51:D66) -> 6701.29 | E16: =D16/$D$5 -> 0.1034294 | F16: =SUM(F51:F66) -> 9746.41 | G16: =F16/$D$5 -> 0.15042855 | H16: =SUM(H51:H66) -> 13574.39 | I16: =H16/$D$5 -> 0.20951056 | J16: =SUM(J51:J66) -> 13440.32 | K16: =J16/$D$5 -> 0.20744129 | L16: =SUM(L51:L66) -> 13314.93 | M16: =L16/$D$5 -> 0.20550598 | N16: =SUM(N51:N66) -> 10487.5 | O16: =N16/$D$5 -> 0.16186672 | P16: =SUM(P51:P66) -> 10533.69 | Q16: =P16/$D$5 -> 0.16257963 | R16: =SUM(R51:R66) -> 5514.55 | S16: =R16/$D$5 -> 0.085112954 | T16: =SUM(T51:T66) -> 9066.6 | U16: =T16/$D$5 -> 0.13993619 | V16: =SUM(V51:V66) -> 13977.93 | W16: =V16/$D$5 -> 0.21573889 | X16: =SUM(X51:X66) -> 12472.11 | Y16: =X16/$D$5 -> 0.19249769 | Z16: =SUM(Z51:Z66) -> 5909.1 | AA16: =Z16/$D$5 -> 0.091202538 | AB16: =Z16+X16+V16+T16+R16+P16+N16+L16+J16+H16+F16+D16 -> 124738.82 | AC16: =AB16/$AB$5 -> 0.16992498
B17: Compenso Amministratore | D17: {=SUMPRODUCT((IFERROR(MONTH(CASSA!$B7:$B3167)=MONTH(D$2),FALSE))*(CASSA!$G7:$G3167="Compenso Amministratore")*(IFERROR(ROUND(CASSA!$F7:$F3167,2),0)))+ SUMPRODUCT((IFERROR(MONTH(BANCA!$B8:$B4170)=MONTH(D$2),FALSE))*(BANCA!$G8:$G4169="Compenso Amministratore")*(IFERROR(ROUND(BANCA!$F8:$F4170,2),0)))} -> #N/A | E17: =D17/$D$5 -> #N/A | F17: {=SUMPRODUCT((IFERROR(MONTH(CASSA!$B7:$B3167)=MONTH(F$2),FALSE))*(CASSA!$G7:$G3167="Compenso Amministratore")*(IFERROR(ROUND(CASSA!$F7:$F3167,2),0)))+ SUMPRODUCT((IFERROR(MONTH(BANCA!$B8:$B4170)=MONTH(F$2),FALSE))*(BANCA!$G8:$G4169="Compenso Amministratore")*(IFERROR(ROUND(BANCA!$F8:$F4170,2),0)))} -> #N/A | G17: =F17/$D$5 -> #N/A | H17: {=SUMPRODUCT((IFERROR(MONTH(CASSA!$B7:$B3167)=MONTH(H$2),FALSE))*(CASSA!$G7:$G3167="Compenso Amministratore")*(IFERROR(ROUND(CASSA!$F7:$F3167,2),0)))+ SUMPRODUCT((IFERROR(MONTH(BANCA!$B8:$B4170)=MONTH(H$2),FALSE))*(BANCA!$G8:$G4169="Compenso Amministratore")*(IFERROR(ROUND(BANCA!$F8:$F4170,2),0)))} -> #N/A | I17: =H17/$D$5 -> #N/A | J17: {=SUMPRODUCT((IFERROR(MONTH(CASSA!$B7:$B3167)=MONTH(J$2),FALSE))*(CASSA!$G7:$G3167="Compenso Amministratore")*(IFERROR(ROUND(CASSA!$F7:$F3167,2),0)))+ SUMPRODUCT((IFERROR(MONTH(BANCA!$B8:$B4170)=MONTH(J$2),FALSE))*(BANCA!$G8:$G4169="Compenso Amministratore")*(IFERROR(ROUND(BANCA!$F8:$F4170,2),0)))} -> #N/A | K17: =J17/$D$5 -> #N/A | L17: {=SUMPRODUCT((IFERROR(MONTH(CASSA!$B7:$B3167)=MONTH(L$2),FALSE))*(CASSA!$G7:$G3167="Compenso Amministratore")*(IFERROR(ROUND(CASSA!$F7:$F3167,2),0)))+ SUMPRODUCT((IFERROR(MONTH(BANCA!$B8:$B4170)=MONTH(L$2),FALSE))*(BANCA!$G8:$G4169="Compenso Amministratore")*(IFERROR(ROUND(BANCA!$F8:$F4170,2),0)))} -> #N/A | M17: =L17/$D$5 -> #N/A | N17: {=SUMPRODUCT((IFERROR(MONTH(CASSA!$B7:$B3167)=MONTH(N$2),FALSE))*(CASSA!$G7:$G3167="Compenso Amministratore")*(IFERROR(ROUND(CASSA!$F7:$F3167,2),0)))+ SUMPRODUCT((IFERROR(MONTH(BANCA!$B8:$B4170)=MONTH(N$2),FALSE))*(BANCA!$G8:$G4169="Compenso Amministratore")*(IFERROR(ROUND(BANCA!$F8:$F4170,2),0)))} -> #N/A | O17: =N17/$D$5 -> #N/A | P17: {=SUMPRODUCT((IFERROR(MONTH(CASSA!$B7:$B3167)=MONTH(P$2),FALSE))*(CASSA!$G7:$G3167="Compenso Amministratore")*(IFERROR(ROUND(CASSA!$F7:$F3167,2),0)))+ SUMPRODUCT((IFERROR(MONTH(BANCA!$B8:$B4170)=MONTH(P$2),FALSE))*(BANCA!$G8:$G4169="Compenso Amministratore")*(IFERROR(ROUND(BANCA!$F8:$F4170,2),0)))} -> #N/A | Q17: =P17/$D$5 -> #N/A | R17: {=SUMPRODUCT((IFERROR(MONTH(CASSA!$B7:$B3167)=MONTH(R$2),FALSE))*(CASSA!$G7:$G3167="Compenso Amministratore")*(IFERROR(ROUND(CASSA!$F7:$F3167,2),0)))+ SUMPRODUCT((IFERROR(MONTH(BANCA!$B8:$B4170)=MONTH(R$2),FALSE))*(BANCA!$G8:$G4169="Compenso Amministratore")*(IFERROR(ROUND(BANCA!$F8:$F4170,2),0)))} -> #N/A | S17: =R17/$D$5 -> #N/A | T17: {=SUMPRODUCT((IFERROR(MONTH(CASSA!$B7:$B3167)=MONTH(T$2),FALSE))*(CASSA!$G7:$G3167="Compenso Amministratore")*(IFERROR(ROUND(CASSA!$F7:$F3167,2),0)))+ SUMPRODUCT((IFERROR(MONTH(BANCA!$B8:$B4170)=MONTH(T$2),FALSE))*(BANCA!$G8:$G4169="Compenso Amministratore")*(IFERROR(ROUND(BANCA!$F8:$F4170,2),0)))} -> #N/A | U17: =T17/$D$5 -> #N/A | V17: {=SUMPRODUCT((IFERROR(MONTH(CASSA!$B7:$B3167)=MONTH(V$2),FALSE))*(CASSA!$G7:$G3167="Compenso Amministratore")*(IFERROR(ROUND(CASSA!$F7:$F3167,2),0)))+ SUMPRODUCT((IFERROR(MONTH(BANCA!$B8:$B4170)=MONTH(V$2),FALSE))*(BANCA!$G8:$G4169="Compenso Amministratore")*(IFERROR(ROUND(BANCA!$F8:$F4170,2),0)))} -> #N/A | W17: =V17/$D$5 -> #N/A | X17: {=SUMPRODUCT((IFERROR(MONTH(CASSA!$B7:$B3167)=MONTH(X$2),FALSE))*(CASSA!$G7:$G3167="Compenso Amministratore")*(IFERROR(ROUND(CASSA!$F7:$F3167,2),0)))+ SUMPRODUCT((IFERROR(MONTH(BANCA!$B8:$B4170)=MONTH(X$2),FALSE))*(BANCA!$G8:$G4169="Compenso Amministratore")*(IFERROR(ROUND(BANCA!$F8:$F4170,2),0)))} -> #N/A | Y17: =X17/$D$5 -> #N/A | Z17: {=SUMPRODUCT((IFERROR(MONTH(CASSA!$B7:$B3167)=MONTH(Z$2),FALSE))*(CASSA!$G7:$G3167="Compenso Amministratore")*(IFERROR(ROUND(CASSA!$F7:$F3167,2),0)))+ SUMPRODUCT((IFERROR(MONTH(BANCA!$B8:$B4170)=MONTH(Z$2),FALSE))*(BANCA!$G8:$G4169="Compenso Amministratore")*(IFERROR(ROUND(BANCA!$F8:$F4170,2),0)))} -> #N/A | AA17: =Z17/$D$5 -> #N/A | AB17: =Z17+X17+V17+T17+R17+P17+N17+L17+J17+H17+F17+D17 -> #N/A | AC17: =AB17/$AB$5 -> #N/A
B18: Imposte e tasse | D18: =D69 -> 0 | F18: =F69 -> 0 | H18: =H69 -> 0 | J18: =J69 -> 0 | L18: =L69 -> 0 | N18: =N69 -> 0 | P18: =P69 -> 2300.12 | R18: =R69 -> 4616.11 | T18: =T69 -> 467.84 | V18: =V69 -> 0 | X18: =X69 -> 0 | Z18: =Z69 -> 0 | AB18: =SUM(D18:Z18) -> 7384.07 | AC18: =AB18/$AB$5 -> 0.010058921
B19: Investimenti | D19: =D72 -> 0 | F19: =F72 -> 12886.07 | H19: =H72 -> 1762.82 | J19: =J72 -> 10982.2 | L19: =L72 -> 3870.6 | N19: =N72 -> 1560.66 | P19: =P72 -> 18749.1 | R19: =R72 -> -25545.07 | T19: 9 | V19: =V72 -> 0 | X19: =X72 -> 0 | Z19: =Z72 -> 0 | AB19: =Z19+X19+V19+T19+R19+P19+N19+L19+J19+H19+F19+D19 -> 24275.38 | AC19: =AB19/$AB$5 -> 0.033069043
B20: Rimb Capitale Finanziamenti | D20: {=SUMPRODUCT((IFERROR(MONTH(CASSA!$B7:$B4163)=MONTH(D$2),FALSE))*(CASSA!$G7:$G4163="Rimborso finanziamento SOCIO")*(IFERROR(ROUND(CASSA!$F7:$F4163,2),0)))+ SUMPRODUCT((IFERROR(MONTH(BANCA!$B8:$B4170)=MONTH(D$2),FALSE))*(BANCA!$G8:$G4169="Rimborso finanziamento SOCIO")*(IFERROR(ROUND(BANCA!$F8:$F4170,2),0)))+ SUMPRODUCT((IFERROR(MONTH(CASSA!$B7:$B4163)=MONTH(D$2),FALSE))*(CASSA!$G7:$G4163="Rimborso capitale mutuo")*(IFERROR(ROUND(CASSA!$F7:$F4163,2),0)))+ SUMPRODUCT((IFERROR(MONTH(BANCA!$B8:$B4170)=MONTH(D$2),FALSE))*(BANCA!$G8:$G4169="Rimborso capitale mutuo")*(IFERROR(ROUND(BANCA!$F8:$F4170,2),0)))} -> #N/A | F20: {=SUMPRODUCT((IFERROR(MONTH(CASSA!$B7:$B4163)=MONTH(F$2),FALSE))*(CASSA!$G7:$G4163="Rimborso finanziamento SOCIO")*(IFERROR(ROUND(CASSA!$F7:$F4163,2),0)))+ SUMPRODUCT((IFERROR(MONTH(BANCA!$B8:$B4170)=MONTH(F$2),FALSE))*(BANCA!$G8:$G4169="Rimborso finanziamento SOCIO")*(IFERROR(ROUND(BANCA!$F8:$F4170,2),0)))+ SUMPRODUCT((IFERROR(MONTH(CASSA!$B7:$B4163)=MONTH(F$2),FALSE))*(CASSA!$G7:$G4163="Rimborso capitale mutuo")*(IFERROR(ROUND(CASSA!$F7:$F4163,2),0)))+ SUMPRODUCT((IFERROR(MONTH(BANCA!$B8:$B4170)=MONTH(F$2),FALSE))*(BANCA!$G8:$G4169="Rimborso capitale mutuo")*(IFERROR(ROUND(BANCA!$F8:$F4170,2),0)))} -> #N/A | H20: {=SUMPRODUCT((IFERROR(MONTH(CASSA!$B7:$B4163)=MONTH(H$2),FALSE))*(CASSA!$G7:$G4163="Rimborso finanziamento SOCIO")*(IFERROR(ROUND(CASSA!$F7:$F4163,2),0)))+ SUMPRODUCT((IFERROR(MONTH(BANCA!$B8:$B4170)=MONTH(H$2),FALSE))*(BANCA!$G8:$G4169="Rimborso finanziamento SOCIO")*(IFERROR(ROUND(BANCA!$F8:$F4170,2),0)))+ SUMPRODUCT((IFERROR(MONTH(CASSA!$B7:$B4163)=MONTH(H$2),FALSE))*(CASSA!$G7:$G4163="Rimborso capitale mutuo")*(IFERROR(ROUND(CASSA!$F7:$F4163,2),0)))+ SUMPRODUCT((IFERROR(MONTH(BANCA!$B8:$B4170)=MONTH(H$2),FALSE))*(BANCA!$G8:$G4169="Rimborso capitale mutuo")*(IFERROR(ROUND(BANCA!$F8:$F4170,2),0)))} -> #N/A | J20: {=SUMPRODUCT((IFERROR(MONTH(CASSA!$B7:$B4163)=MONTH(J$2),FALSE))*(CASSA!$G7:$G4163="Rimborso finanziamento SOCIO")*(IFERROR(ROUND(CASSA!$F7:$F4163,2),0)))+ SUMPRODUCT((IFERROR(MONTH(BANCA!$B8:$B4170)=MONTH(J$2),FALSE))*(BANCA!$G8:$G4169="Rimborso finanziamento SOCIO")*(IFERROR(ROUND(BANCA!$F8:$F4170,2),0)))+ SUMPRODUCT((IFERROR(MONTH(CASSA!$B7:$B4163)=MONTH(J$2),FALSE))*(CASSA!$G7:$G4163="Rimborso capitale mutuo")*(IFERROR(ROUND(CASSA!$F7:$F4163,2),0)))+ SUMPRODUCT((IFERROR(MONTH(BANCA!$B8:$B4170)=MONTH(J$2),FALSE))*(BANCA!$G8:$G4169="Rimborso capitale mutuo")*(IFERROR(ROUND(BANCA!$F8:$F4170,2),0)))} -> #N/A | L20: {=SUMPRODUCT((IFERROR(MONTH(CASSA!$B7:$B4163)=MONTH(L$2),FALSE))*(CASSA!$G7:$G4163="Rimborso finanziamento SOCIO")*(IFERROR(ROUND(CASSA!$F7:$F4163,2),0)))+ SUMPRODUCT((IFERROR(MONTH(BANCA!$B8:$B4170)=MONTH(L$2),FALSE))*(BANCA!$G8:$G4169="Rimborso finanziamento SOCIO")*(IFERROR(ROUND(BANCA!$F8:$F4170,2),0)))+ SUMPRODUCT((IFERROR(MONTH(CASSA!$B7:$B4163)=MONTH(L$2),FALSE))*(CASSA!$G7:$G4163="Rimborso capitale mutuo")*(IFERROR(ROUND(CASSA!$F7:$F4163,2),0)))+ SUMPRODUCT((IFERROR(MONTH(BANCA!$B8:$B4170)=MONTH(L$2),FALSE))*(BANCA!$G8:$G4169="Rimborso capitale mutuo")*(IFERROR(ROUND(BANCA!$F8:$F4170,2),0)))} -> #N/A | N20: {=SUMPRODUCT((IFERROR(MONTH(CASSA!$B7:$B4163)=MONTH(N$2),FALSE))*(CASSA!$G7:$G4163="Rimborso finanziamento SOCIO")*(IFERROR(ROUND(CASSA!$F7:$F4163,2),0)))+ SUMPRODUCT((IFERROR(MONTH(BANCA!$B8:$B4170)=MONTH(N$2),FALSE))*(BANCA!$G8:$G4169="Rimborso finanziamento SOCIO")*(IFERROR(ROUND(BANCA!$F8:$F4170,2),0)))+ SUMPRODUCT((IFERROR(MONTH(CASSA!$B7:$B4163)=MONTH(N$2),FALSE))*(CASSA!$G7:$G4163="Rimborso capitale mutuo")*(IFERROR(ROUND(CASSA!$F7:$F4163,2),0)))+ SUMPRODUCT((IFERROR(MONTH(BANCA!$B8:$B4170)=MONTH(N$2),FALSE))*(BANCA!$G8:$G4169="Rimborso capitale mutuo")*(IFERROR(ROUND(BANCA!$F8:$F4170,2),0)))} -> #N/A | P20: {=SUMPRODUCT((IFERROR(MONTH(CASSA!$B7:$B4163)=MONTH(P$2),FALSE))*(CASSA!$G7:$G4163="Rimborso finanziamento SOCIO")*(IFERROR(ROUND(CASSA!$F7:$F4163,2),0)))+ SUMPRODUCT((IFERROR(MONTH(BANCA!$B8:$B4170)=MONTH(P$2),FALSE))*(BANCA!$G8:$G4169="Rimborso finanziamento SOCIO")*(IFERROR(ROUND(BANCA!$F8:$F4170,2),0)))+ SUMPRODUCT((IFERROR(MONTH(CASSA!$B7:$B4163)=MONTH(P$2),FALSE))*(CASSA!$G7:$G4163="Rimborso capitale mutuo")*(IFERROR(ROUND(CASSA!$F7:$F4163,2),0)))+ SUMPRODUCT((IFERROR(MONTH(BANCA!$B8:$B4170)=MONTH(P$2),FALSE))*(BANCA!$G8:$G4169="Rimborso capitale mutuo")*(IFERROR(ROUND(BANCA!$F8:$F4170,2),0)))} -> #N/A | R20: {=SUMPRODUCT((IFERROR(MONTH(CASSA!$B7:$B4163)=MONTH(R$2),FALSE))*(CASSA!$G7:$G4163="Rimborso finanziamento SOCIO")*(IFERROR(ROUND(CASSA!$F7:$F4163,2),0)))+ SUMPRODUCT((IFERROR(MONTH(BANCA!$B8:$B4170)=MONTH(R$2),FALSE))*(BANCA!$G8:$G4169="Rimborso finanziamento SOCIO")*(IFERROR(ROUND(BANCA!$F8:$F4170,2),0)))+ SUMPRODUCT((IFERROR(MONTH(CASSA!$B7:$B4163)=MONTH(R$2),FALSE))*(CASSA!$G7:$G4163="Rimborso capitale mutuo")*(IFERROR(ROUND(CASSA!$F7:$F4163,2),0)))+ SUMPRODUCT((IFERROR(MONTH(BANCA!$B8:$B4170)=MONTH(R$2),FALSE))*(BANCA!$G8:$G4169="Rimborso capitale mutuo")*(IFERROR(ROUND(BANCA!$F8:$F4170,2),0)))} -> #N/A | T20: {=SUMPRODUCT((IFERROR(MONTH(CASSA!$B7:$B4163)=MONTH(T$2),FALSE))*(CASSA!$G7:$G4163="Rimborso finanziamento SOCIO")*(IFERROR(ROUND(CASSA!$F7:$F4163,2),0)))+ SUMPRODUCT((IFERROR(MONTH(BANCA!$B8:$B4170)=MONTH(T$2),FALSE))*(BANCA!$G8:$G4169="Rimborso finanziamento SOCIO")*(IFERROR(ROUND(BANCA!$F8:$F4170,2),0)))+ SUMPRODUCT((IFERROR(MONTH(CASSA!$B7:$B4163)=MONTH(T$2),FALSE))*(CASSA!$G7:$G4163="Rimborso capitale mutuo")*(IFERROR(ROUND(CASSA!$F7:$F4163,2),0)))+ SUMPRODUCT((IFERROR(MONTH(BANCA!$B8:$B4170)=MONTH(T$2),FALSE))*(BANCA!$G8:$G4169="Rimborso capitale mutuo")*(IFERROR(ROUND(BANCA!$F8:$F4170,2),0)))} -> #N/A | V20: {=SUMPRODUCT((IFERROR(MONTH(CASSA!$B7:$B4163)=MONTH(V$2),FALSE))*(CASSA!$G7:$G4163="Rimborso finanziamento SOCIO")*(IFERROR(ROUND(CASSA!$F7:$F4163,2),0)))+ SUMPRODUCT((IFERROR(MONTH(BANCA!$B8:$B4170)=MONTH(V$2),FALSE))*(BANCA!$G8:$G4169="Rimborso finanziamento SOCIO")*(IFERROR(ROUND(BANCA!$F8:$F4170,2),0)))+ SUMPRODUCT((IFERROR(MONTH(CASSA!$B7:$B4163)=MONTH(V$2),FALSE))*(CASSA!$G7:$G4163="Rimborso capitale mutuo")*(IFERROR(ROUND(CASSA!$F7:$F4163,2),0)))+ SUMPRODUCT((IFERROR(MONTH(BANCA!$B8:$B4170)=MONTH(V$2),FALSE))*(BANCA!$G8:$G4169="Rimborso capitale mutuo")*(IFERROR(ROUND(BANCA!$F8:$F4170,2),0)))} -> #N/A | X20: {=SUMPRODUCT((IFERROR(MONTH(CASSA!$B7:$B4163)=MONTH(X$2),FALSE))*(CASSA!$G7:$G4163="Rimborso finanziamento SOCIO")*(IFERROR(ROUND(CASSA!$F7:$F4163,2),0)))+ SUMPRODUCT((IFERROR(MONTH(BANCA!$B8:$B4170)=MONTH(X$2),FALSE))*(BANCA!$G8:$G4169="Rimborso finanziamento SOCIO")*(IFERROR(ROUND(BANCA!$F8:$F4170,2),0)))+ SUMPRODUCT((IFERROR(MONTH(CASSA!$B7:$B4163)=MONTH(X$2),FALSE))*(CASSA!$G7:$G4163="Rimborso capitale mutuo")*(IFERROR(ROUND(CASSA!$F7:$F4163,2),0)))+ SUMPRODUCT((IFERROR(MONTH(BANCA!$B8:$B4170)=MONTH(X$2),FALSE))*(BANCA!$G8:$G4169="Rimborso capitale mutuo")*(IFERROR(ROUND(BANCA!$F8:$F4170,2),0)))} -> #N/A | Z20: {=SUMPRODUCT((IFERROR(MONTH(CASSA!$B7:$B4163)=MONTH(Z$2),FALSE))*(CASSA!$G7:$G4163="Rimborso finanziamento SOCIO")*(IFERROR(ROUND(CASSA!$F7:$F4163,2),0)))+ SUMPRODUCT((IFERROR(MONTH(BANCA!$B8:$B4170)=MONTH(Z$2),FALSE))*(BANCA!$G8:$G4169="Rimborso finanziamento SOCIO")*(IFERROR(ROUND(BANCA!$F8:$F4170,2),0)))+ SUMPRODUCT((IFERROR(MONTH(CASSA!$B7:$B4163)=MONTH(Z$2),FALSE))*(CASSA!$G7:$G4163="Rimborso capitale mutuo")*(IFERROR(ROUND(CASSA!$F7:$F4163,2),0)))+ SUMPRODUCT((IFERROR(MONTH(BANCA!$B8:$B4170)=MONTH(Z$2),FALSE))*(BANCA!$G8:$G4169="Rimborso capitale mutuo")*(IFERROR(ROUND(BANCA!$F8:$F4170,2),0)))} -> #N/A | AB20: =SUM(D20:Z20) -> #N/A
B21: Saldo IVA | D21: =D78 -> -663.95 | F21: =F78 -> 2027.93 | H21: =H78 -> 4902.49 | J21: =J78 -> 8717.2 | L21: =L78 -> 9620.81 | N21: =N78 -> 1306.9 | P21: =P78 -> 6368.74 | R21: =R78 -> 143.67 | T21: =T78 -> 2133.36 | V21: =V78 -> 2109.05 | X21: =X78 -> 541.6 | Z21: =Z78 -> 2716.48 | AB21: =SUM(D21:Z21) -> 39924.28
B23: COSTI PERSONALE
B24: Costo personale | D24: {=SUMPRODUCT((IFERROR(MONTH(CASSA!$B7:$B3166)=MONTH(D$2),FALSE))*(CASSA!$G7:$G3166="Retribuzione del personale")*(IFERROR(ROUND(CASSA!$F7:$F3166,2),0)))+ SUMPRODUCT((IFERROR(MONTH(BANCA!$B8:$B4163)=MONTH(D$2),FALSE))*(BANCA!$G8:$G4163="Retribuzione del personale")*(IFERROR(ROUND(BANCA!$F8:$F4163,2),0)))} -> 3507 | F24: {=SUMPRODUCT((IFERROR(MONTH(CASSA!$B7:$B3166)=MONTH(F$2),FALSE))*(CASSA!$G7:$G3166="Retribuzione del personale")*(IFERROR(ROUND(CASSA!$F7:$F3166,2),0)))+ SUMPRODUCT((IFERROR(MONTH(BANCA!$B8:$B4163)=MONTH(F$2),FALSE))*(BANCA!$G8:$G4163="Retribuzione del personale")*(IFERROR(ROUND(BANCA!$F8:$F4163,2),0)))} -> 3424 | H24: {=SUMPRODUCT((IFERROR(MONTH(CASSA!$B7:$B3166)=MONTH(H$2),FALSE))*(CASSA!$G7:$G3166="Retribuzione del personale")*(IFERROR(ROUND(CASSA!$F7:$F3166,2),0)))+ SUMPRODUCT((IFERROR(MONTH(BANCA!$B8:$B4163)=MONTH(H$2),FALSE))*(BANCA!$G8:$G4163="Retribuzione del personale")*(IFERROR(ROUND(BANCA!$F8:$F4163,2),0)))} -> 3674 | J24: {=SUMPRODUCT((IFERROR(MONTH(CASSA!$B7:$B3166)=MONTH(J$2),FALSE))*(CASSA!$G7:$G3166="Retribuzione del personale")*(IFERROR(ROUND(CASSA!$F7:$F3166,2),0)))+ SUMPRODUCT((IFERROR(MONTH(BANCA!$B8:$B4163)=MONTH(J$2),FALSE))*(BANCA!$G8:$G4163="Retribuzione del personale")*(IFERROR(ROUND(BANCA!$F8:$F4163,2),0)))} -> 3570 | L24: {=SUMPRODUCT((IFERROR(MONTH(CASSA!$B7:$B3166)=MONTH(L$2),FALSE))*(CASSA!$G7:$G3166="Retribuzione del personale")*(IFERROR(ROUND(CASSA!$F7:$F3166,2),0)))+ SUMPRODUCT((IFERROR(MONTH(BANCA!$B8:$B4163)=MONTH(L$2),FALSE))*(BANCA!$G8:$G4163="Retribuzione del personale")*(IFERROR(ROUND(BANCA!$F8:$F4163,2),0)))} -> 6356 | N24: {=SUMPRODUCT((IFERROR(MONTH(CASSA!$B7:$B3166)=MONTH(N$2),FALSE))*(CASSA!$G7:$G3166="Retribuzione del personale")*(IFERROR(ROUND(CASSA!$F7:$F3166,2),0)))+ SUMPRODUCT((IFERROR(MONTH(BANCA!$B8:$B4163)=MONTH(N$2),FALSE))*(BANCA!$G8:$G4163="Retribuzione del personale")*(IFERROR(ROUND(BANCA!$F8:$F4163,2),0)))} -> 6003 | P24: {=SUMPRODUCT((IFERROR(MONTH(CASSA!$B7:$B3166)=MONTH(P$2),FALSE))*(CASSA!$G7:$G3166="Retribuzione del personale")*(IFERROR(ROUND(CASSA!$F7:$F3166,2),0)))+ SUMPRODUCT((IFERROR(MONTH(BANCA!$B8:$B4163)=MONTH(P$2),FALSE))*(BANCA!$G8:$G4163="Retribuzione del personale")*(IFERROR(ROUND(BANCA!$F8:$F4163,2),0)))} -> 5501 | R24: {=SUMPRODUCT((IFERROR(MONTH(CASSA!$B7:$B3166)=MONTH(R$2),FALSE))*(CASSA!$G7:$G3166="Retribuzione del personale")*(IFERROR(ROUND(CASSA!$F7:$F3166,2),0)))+ SUMPRODUCT((IFERROR(MONTH(BANCA!$B8:$B4163)=MONTH(R$2),FALSE))*(BANCA!$G8:$G4163="Retribuzione del personale")*(IFERROR(ROUND(BANCA!$F8:$F4163,2),0)))} -> 6227 | T24: {=SUMPRODUCT((IFERROR(MONTH(CASSA!$B7:$B3166)=MONTH(T$2),FALSE))*(CASSA!$G7:$G3166="Retribuzione del personale")*(IFERROR(ROUND(CASSA!$F7:$F3166,2),0)))+ SUMPRODUCT((IFERROR(MONTH(BANCA!$B8:$B4163)=MONTH(T$2),FALSE))*(BANCA!$G8:$G4163="Retribuzione del personale")*(IFERROR(ROUND(BANCA!$F8:$F4163,2),0)))} -> 5363 | V24: {=SUMPRODUCT((IFERROR(MONTH(CASSA!$B7:$B3166)=MONTH(V$2),FALSE))*(CASSA!$G7:$G3166="Retribuzione del personale")*(IFERROR(ROUND(CASSA!$F7:$F3166,2),0)))+ SUMPRODUCT((IFERROR(MONTH(BANCA!$B8:$B4163)=MONTH(V$2),FALSE))*(BANCA!$G8:$G4163="Retribuzione del personale")*(IFERROR(ROUND(BANCA!$F8:$F4163,2),0)))} -> 6617 | X24: {=SUMPRODUCT((IFERROR(MONTH(CASSA!$B7:$B3166)=MONTH(X$2),FALSE))*(CASSA!$G7:$G3166="Retribuzione del personale")*(IFERROR(ROUND(CASSA!$F7:$F3166,2),0)))+ SUMPRODUCT((IFERROR(MONTH(BANCA!$B8:$B4163)=MONTH(X$2),FALSE))*(BANCA!$G8:$G4163="Retribuzione del personale")*(IFERROR(ROUND(BANCA!$F8:$F4163,2),0)))} -> 12265 | Z24: {=SUMPRODUCT((IFERROR(MONTH(CASSA!$B7:$B3166)=MONTH(Z$2),FALSE))*(CASSA!$G7:$G3166="Retribuzione del personale")*(IFERROR(ROUND(CASSA!$F7:$F3166,2),0)))+ SUMPRODUCT((IFERROR(MONTH(BANCA!$B8:$B4163)=MONTH(Z$2),FALSE))*(BANCA!$G8:$G4163="Retribuzione del personale")*(IFERROR(ROUND(BANCA!$F8:$F4163,2),0)))} -> 0 | AB24: =SUM(D24:Z24) -> 62507 | AC24: OK
