Workbook

Sheet MAPPATURA
A1: MAPPATURA DELLE VOCI DI CONTO SUL CASH FLOW
A2: Fonte di verita' della riclassificazione. Un movimento si registra sempre sulla voce di dettaglio: famiglia e sottogruppo sono derivati, mai scelti a mano.
A4: Codice | B4: Sezione | C4: Mastro | D4: Gruppo | E4: Voce di conto | F4: Famiglia | G4: Sottogruppo | H4: Nome sottogruppo | I4: Segno | J4: Cassa | K4: Regola centro di costo | L4: Note
A5: 10.01 | B5: RICAVI | C5: 10 - Ricavi delle vendite e delle prestazioni | E5: Corrispettivi | F5: A | G5: A1 | H5: Corrispettivi | I5: Entrata | J5: SI | K5: Obbligatorio
A6: 10.09 | B6: RICAVI | C6: 10 - Ricavi delle vendite e delle prestazioni | E6: Resi, sconti e abbuoni su vendite | F6: A | G6: A1 | H6: Corrispettivi | I6: Rettifica | J6: SI | K6: Obbligatorio | L6: Segno negativo: rettifica dei ricavi
A7: 11.01 | B7: RICAVI | C7: 11 - Ricavi eventi | E7: Ricavi eventi serali (ingressi e consumazioni) | F7: A | G7: A2 | H7: Eventi | I7: Entrata | J7: SI | K7: Obbligatorio
A8: 11.02 | B8: RICAVI | C8: 11 - Ricavi eventi | E8: Ricavi eventi privati e compleanni | F8: A | G8: A2 | H8: Eventi | I8: Entrata | J8: SI | K8: Obbligatorio
A9: 12.01 | B9: RICAVI | C9: 12 - Altri ricavi e proventi | E9: Proventi vari | F9: A | G9: A3 | H9: Altri proventi | I9: Entrata | J9: SI | K9: Default STR
A10: 12.02 | B10: RICAVI | C10: 12 - Altri ricavi e proventi | E10: Contributi in conto esercizio | F10: A | G10: A3 | H10: Altri proventi | I10: Entrata | J10: SI | K10: Default STR
A11: 12.03 | B11: RICAVI | C11: 12 - Altri ricavi e proventi | E11: Rimborsi assicurativi | F11: A | G11: A3 | H11: Altri proventi | I11: Entrata | J11: SI | K11: Default STR
A12: 12.04 | B12: RICAVI | C12: 12 - Altri ricavi e proventi | E12: Premi, bonus e contributi da fornitori | F12: A | G12: A3 | H12: Altri proventi | I12: Entrata | J12: SI | K12: Default STR
A13: 12.06 | B13: RICAVI | C13: 12 - Altri ricavi e proventi | E13: Sopravvenienze attive | F13: A | G13: A3 | H13: Altri proventi | I13: Entrata | J13: SI | K13: Default STR
A14: 12.07 | B14: RICAVI | C14: 12 - Altri ricavi e proventi | E14: Plusvalenze da alienazione cespiti | I14: - | J14: NO | K14: Default STR | L14: Fuori cash flow: Plusvalenza contabile; l'incasso della cessione e' 40.1.04
A15: 13.01 | B15: RICAVI | C15: 13 - Proventi finanziari | E15: Interessi attivi bancari | F15: A | G15: A3 | H15: Altri proventi | I15: Entrata | J15: SI | K15: Default STR
A16: 13.02 | B16: RICAVI | C16: 13 - Proventi finanziari | E16: Altri proventi finanziari | F16: A | G16: A3 | H16: Altri proventi | I16: Entrata | J16: SI | K16: Default STR
A17: 20.1.01 | B17: COSTI | C17: 20 - Materie prime, sussidiarie e merci | D17: 20.1 - Beverage alcolico | E17: Birra fusto | F17: B | G17: B1 | H17: Beverage alcolico | I17: Uscita | J17: SI | K17: Obbligatorio
A18: 20.1.02 | B18: COSTI | C18: 20 - Materie prime, sussidiarie e merci | D18: 20.1 - Beverage alcolico | E18: Birra bottiglia e lattina | F18: B | G18: B1 | H18: Beverage alcolico | I18: Uscita | J18: SI | K18: Obbligatorio
A19: 20.1.03 | B19: COSTI | C19: 20 - Materie prime, sussidiarie e merci | D19: 20.1 - Beverage alcolico | E19: Distillati e liquori | F19: B | G19: B1 | H19: Beverage alcolico | I19: Uscita | J19: SI | K19: Obbligatorio
A20: 20.1.04 | B20: COSTI | C20: 20 - Materie prime, sussidiarie e merci | D20: 20.1 - Beverage alcolico | E20: Vermouth, bitter e aperitivi | F20: B | G20: B1 | H20: Beverage alcolico | I20: Uscita | J20: SI | K20: Obbligatorio
A21: 20.1.05 | B21: COSTI | C21: 20 - Materie prime, sussidiarie e merci | D21: 20.1 - Beverage alcolico | E21: Vini | F21: B | G21: B1 | H21: Beverage alcolico | I21: Uscita | J21: SI | K21: Obbligatorio
A22: 20.2.01 | B22: COSTI | C22: 20 - Materie prime, sussidiarie e merci | D22: 20.2 - Beverage analcolico | E22: Bibite e soft drink | F22: B | G22: B2 | H22: Beverage analcolico | I22: Uscita | J22: SI | K22: Obbligatorio
A23: 20.2.02 | B23: COSTI | C23: 20 - Materie prime, sussidiarie e merci | D23: 20.2 - Beverage analcolico | E23: Acqua minerale | F23: B | G23: B2 | H23: Beverage analcolico | I23: Uscita | J23: SI | K23: Obbligatorio
A24: 20.2.03 | B24: COSTI | C24: 20 - Materie prime, sussidiarie e merci | D24: 20.2 - Beverage analcolico | E24: Succhi, nettari e centrifugati | F24: B | G24: B2 | H24: Beverage analcolico | I24: Uscita | J24: SI | K24: Obbligatorio
A25: 20.2.04 | B25: COSTI | C25: 20 - Materie prime, sussidiarie e merci | D25: 20.2 - Beverage analcolico | E25: Sciroppi, purea e mixer | F25: B | G25: B2 | H25: Beverage analcolico | I25: Uscita | J25: SI | K25: Obbligatorio
A26: 20.3.01 | B26: COSTI | C26: 20 - Materie prime, sussidiarie e merci | D26: 20.3 - Caffetteria | E26: Caffè | F26: B | G26: B3 | H26: Caffetteria | I26: Uscita | J26: SI | K26: Obbligatorio
A27: 20.3.02 | B27: COSTI | C27: 20 - Materie prime, sussidiarie e merci | D27: 20.3 - Caffetteria | E27: Latte e derivati | F27: B | G27: B3 | H27: Caffetteria | I27: Uscita | J27: SI | K27: Obbligatorio
A28: 20.3.03 | B28: COSTI | C28: 20 - Materie prime, sussidiarie e merci | D28: 20.3 - Caffetteria | E28: Tè, infusi e cioccolata | F28: B | G28: B3 | H28: Caffetteria | I28: Uscita | J28: SI | K28: Obbligatorio
... A39: 20.5.05 | B39: COSTI | C39: 20 - Materie prime, sussidiarie e merci | D39: 20.5 - Consumabili di servizio | E39: Altri materiali di consumo | F39: B | G39: B5 | H39: Consumabili di servizio | I39: Uscita | J39: SI | K39: Obbligatorio
A40: 20.6.01 | B40: COSTI | C40: 20 - Materie prime, sussidiarie e merci | D40: 20.6 - Rettifiche e variazioni | E40: Resi, sconti e premi su acquisti | F40: B | G40: B6 | H40: Rettifiche su acquisti | I40: Rettifica | J40: SI | K40: Obbligatorio | L40: Segno negativo: rettifica dei costi
A41: 20.6.02 | B41: COSTI | C41: 20 - Materie prime, sussidiarie e merci | D41: 20.6 - Rettifiche e variazioni | E41: Rimanenze iniziali | I41: - | J41: NO | K41: Obbligatorio | L41: Fuori cash flow: Variazione di magazzino
A42: 20.6.03 | B42: COSTI | C42: 20 - Materie prime, sussidiarie e merci | D42: 20.6 - Rettifiche e variazioni | E42: Rimanenze finali | I42: - | J42: NO | K42: Obbligatorio | L42: Segno negativo: riduce il consumo | Fuori cash flow: Variazione di magazzino
A43: 20.6.04 | B43: COSTI | C43: 20 - Materie prime, sussidiarie e merci | D43: 20.6 - Rettifiche e variazioni | E43: Ammanchi, rotture e cali | I43: - | J43: NO | K43: Obbligatorio | L43: Fuori cash flow: Riclassifica di valore, nessun esborso
A44: 20.6.05 | B44: COSTI | C44: 20 - Materie prime, sussidiarie e merci | D44: 20.6 - Rettifiche e variazioni | E44: Omaggi, autoconsumo e staff meal | I44: - | J44: NO | K44: Obbligatorio | L44: Fuori cash flow: Riclassifica di valore, nessun esborso
A45: 21.01 | B45: COSTI | C45: 21 - Attrezzatura e beni strumentali minuti | E45: Vetreria e attrezzatura bar | F45: E | G45: E5 | H45: Attrezzatura e allestimenti | I45: Uscita | J45: SI | K45: Obbligatorio
A46: 21.02 | B46: COSTI | C46: 21 - Attrezzatura e beni strumentali minuti | E46: Stoviglie, posateria e complementi sala | F46: E | G46: E5 | H46: Attrezzatura e allestimenti | I46: Uscita | J46: SI | K46: Obbligatorio
A47: 21.03 | B47: COSTI | C47: 21 - Attrezzatura e beni strumentali minuti | E47: Piccola attrezzatura cucina | F47: E | G47: E5 | H47: Attrezzatura e allestimenti | I47: Uscita | J47: SI | K47: Obbligatorio
A48: 21.04 | B48: COSTI | C48: 21 - Attrezzatura e beni strumentali minuti | E48: Beni strumentali < 516,46 EUR | F48: E | G48: E5 | H48: Attrezzatura e allestimenti | I48: Uscita | J48: SI | K48: Obbligatorio | L48: Deducibili al 100% nell'esercizio
A49: 21.05 | B49: COSTI | C49: 21 - Attrezzatura e beni strumentali minuti | E49: Arredi e complementi minuti | F49: E | G49: E5 | H49: Attrezzatura e allestimenti | I49: Uscita | J49: SI | K49: Obbligatorio
A50: 21.06 | B50: COSTI | C50: 21 - Attrezzatura e beni strumentali minuti | E50: Divise e abbigliamento personale | F50: E | G50: E5 | H50: Attrezzatura e allestimenti | I50: Uscita | J50: SI | K50: Obbligatorio
A51: 21.07 | B51: COSTI | C51: 21 - Attrezzatura e beni strumentali minuti | E51: Allestimenti, fiori e decorazioni locale | F51: E | G51: E5 | H51: Attrezzatura e allestimenti | I51: Uscita | J51: SI | K51: Obbligatorio | L51: Decorazioni ordinarie del locale (non evento)
...

Sheet CASH FLOW
A1: CASH FLOW — consuntivo
A2: Solo movimenti che toccano cassa o banca. Entrate positive, uscite negative. Le voci di dettaglio sono nascoste: usa i pulsanti + a sinistra per aprirle.
A4: Codice | B4: Voce | C4: GEN | D4: FEB | E4: MAR | F4: APR | G4: MAG | H4: GIU | I4: LUG | J4: AGO | K4: SET | L4: OTT | M4: NOV | N4: DIC | O4: TOTALE
A5: A | B5: INCASSI OPERATIVI | C5: =SUBTOTAL(9,C6:C19) | D5: =SUBTOTAL(9,D6:D19) | E5: =SUBTOTAL(9,E6:E19) | F5: =SUBTOTAL(9,F6:F19) | G5: =SUBTOTAL(9,G6:G19) | H5: =SUBTOTAL(9,H6:H19) | I5: =SUBTOTAL(9,I6:I19) | J5: =SUBTOTAL(9,J6:J19) | ... O5: =SUBTOTAL(9,O6:O19)
A6: A1 | B6: Corrispettivi | C6: =SUBTOTAL(9,C7:C8) | D6: =SUBTOTAL(9,D7:D8) | E6: =SUBTOTAL(9,E7:E8) | F6: =SUBTOTAL(9,F7:F8) | G6: =SUBTOTAL(9,G7:G8) | H6: =SUBTOTAL(9,H7:H8) | I6: =SUBTOTAL(9,I7:I8) | J6: =SUBTOTAL(9,J7:J8) | ... O6: =SUBTOTAL(9,O7:O8)
A7: 10.01 | B7: Corrispettivi | O7: =SUM(C7:N7)
A8: 10.09 | B8: Resi, sconti e abbuoni su vendite | O8: =SUM(C8:N8)
A9: A2 | B9: Eventi | C9: =SUBTOTAL(9,C10:C11) | D9: =SUBTOTAL(9,D10:D11) | E9: =SUBTOTAL(9,E10:E11) | F9: =SUBTOTAL(9,F10:F11) | G9: =SUBTOTAL(9,G10:G11) | H9: =SUBTOTAL(9,H10:H11) | I9: =SUBTOTAL(9,I10:I11) | J9: =SUBTOTAL(9,J10:J11) | ... O9: =SUBTOTAL(9,O10:O11)
A10: 11.01 | B10: Ricavi eventi serali (ingressi e consumazioni) | O10: =SUM(C10:N10)
A11: 11.02 | B11: Ricavi eventi privati e compleanni | O11: =SUM(C11:N11)
A12: A3 | B12: Altri proventi | C12: =SUBTOTAL(9,C13:C19) | D12: =SUBTOTAL(9,D13:D19) | E12: =SUBTOTAL(9,E13:E19) | F12: =SUBTOTAL(9,F13:F19) | G12: =SUBTOTAL(9,G13:G19) | H12: =SUBTOTAL(9,H13:H19) | I12: =SUBTOTAL(9,I13:I19) | J12: =SUBTOTAL(9,J13:J19) | ... O12: =SUBTOTAL(9,O13:O19)
A13: 12.01 | B13: Proventi vari | O13: =SUM(C13:N13)
A14: 12.02 | B14: Contributi in conto esercizio | O14: =SUM(C14:N14)
A15: 12.03 | B15: Rimborsi assicurativi | O15: =SUM(C15:N15)
A16: 12.04 | B16: Premi, bonus e contributi da fornitori | O16: =SUM(C16:N16)
A17: 12.06 | B17: Sopravvenienze attive | O17: =SUM(C17:N17)
A18: 13.01 | B18: Interessi attivi bancari | O18: =SUM(C18:N18)
A19: 13.02 | B19: Altri proventi finanziari | O19: =SUM(C19:N19)
A21: B | B21: COSTO DEL VENDUTO | C21: =SUBTOTAL(9,C22:C51) | D21: =SUBTOTAL(9,D22:D51) | E21: =SUBTOTAL(9,E22:E51) | F21: =SUBTOTAL(9,F22:F51) | G21: =SUBTOTAL(9,G22:G51) | H21: =SUBTOTAL(9,H22:H51) | I21: =SUBTOTAL(9,I22:I51) | J21: =SUBTOTAL(9,J22:J51) | ... O21: =SUBTOTAL(9,O22:O51)
A22: B1 | B22: Beverage alcolico | C22: =SUBTOTAL(9,C23:C27) | D22: =SUBTOTAL(9,D23:D27) | E22: =SUBTOTAL(9,E23:E27) | F22: =SUBTOTAL(9,F23:F27) | G22: =SUBTOTAL(9,G23:G27) | H22: =SUBTOTAL(9,H23:H27) | I22: =SUBTOTAL(9,I23:I27) | J22: =SUBTOTAL(9,J23:J27) | ... O22: =SUBTOTAL(9,O23:O27)
A23: 20.1.01 | B23: Birra fusto | O23: =SUM(C23:N23)
A24: 20.1.02 | B24: Birra bottiglia e lattina | O24: =SUM(C24:N24)
A25: 20.1.03 | B25: Distillati e liquori | O25: =SUM(C25:N25)
A26: 20.1.04 | B26: Vermouth, bitter e aperitivi | O26: =SUM(C26:N26)
A27: 20.1.05 | B27: Vini | O27: =SUM(C27:N27)
A28: B2 | B28: Beverage analcolico | C28: =SUBTOTAL(9,C29:C32) | D28: =SUBTOTAL(9,D29:D32) | E28: =SUBTOTAL(9,E29:E32) | F28: =SUBTOTAL(9,F29:F32) | G28: =SUBTOTAL(9,G29:G32) | H28: =SUBTOTAL(9,H29:H32) | I28: =SUBTOTAL(9,I29:I32) | J28: =SUBTOTAL(9,J29:J32) | ... O28: =SUBTOTAL(9,O29:O32)
A29: 20.2.01 | B29: Bibite e soft drink | O29: =SUM(C29:N29)
A30: 20.2.02 | B30: Acqua minerale | O30: =SUM(C30:N30)
A31: 20.2.03 | B31: Succhi, nettari e centrifugati | O31: =SUM(C31:N31)
A32: 20.2.04 | B32: Sciroppi, purea e mixer | O32: =SUM(C32:N32)
A33: B3 | B33: Caffetteria | C33: =SUBTOTAL(9,C34:C37) | D33: =SUBTOTAL(9,D34:D37) | E33: =SUBTOTAL(9,E34:E37) | F33: =SUBTOTAL(9,F34:F37) | G33: =SUBTOTAL(9,G34:G37) | H33: =SUBTOTAL(9,H34:H37) | I33: =SUBTOTAL(9,I34:I37) | J33: =SUBTOTAL(9,J34:J37) | ... O33: =SUBTOTAL(9,O34:O37)
A34: 20.3.01 | B34: Caffè | O34: =SUM(C34:N34)
A35: 20.3.02 | B35: Latte e derivati | O35: =SUM(C35:N35)
A36: 20.3.03 | B36: Tè, infusi e cioccolata | O36: =SUM(C36:N36)
A37: 20.3.04 | B37: Zucchero e complementi caffetteria | O37: =SUM(C37:N37)
A38: B4 | B38: Food | C38: =SUBTOTAL(9,C39:C43) | D38: =SUBTOTAL(9,D39:D43) | E38: =SUBTOTAL(9,E39:E43) | F38: =SUBTOTAL(9,F39:F43) | G38: =SUBTOTAL(9,G39:G43) | H38: =SUBTOTAL(9,H39:H43) | I38: =SUBTOTAL(9,I39:I43) | J38: =SUBTOTAL(9,J39:J43) | ... O38: =SUBTOTAL(9,O39:O43)
A39: 20.4.01 | B39: Beni alimentari e gastronomia | O39: =SUM(C39:N39)
A40: 20.4.02 | B40: Frutta e verdura | O40: =SUM(C40:N40)
A41: 20.4.03 | B41: Pane e prodotti da forno | O41: =SUM(C41:N41)
A42: 20.4.04 | B42: Pasticceria e dolci | O42: =SUM(C42:N42)
...

Sheet BUDGET
A1: BUDGET — obiettivo
A2: Stessa struttura del consuntivo, riga per riga. Compila le voci di dettaglio: sottogruppi, famiglie e margini si calcolano da soli.
A4: Codice | B4: Voce | C4: GEN | D4: FEB | E4: MAR | F4: APR | G4: MAG | H4: GIU | I4: LUG | J4: AGO | K4: SET | L4: OTT | M4: NOV | N4: DIC | O4: TOTALE
A5: A | B5: INCASSI OPERATIVI | C5: =SUBTOTAL(9,C6:C19) | D5: =SUBTOTAL(9,D6:D19) | E5: =SUBTOTAL(9,E6:E19) | F5: =SUBTOTAL(9,F6:F19) | G5: =SUBTOTAL(9,G6:G19) | H5: =SUBTOTAL(9,H6:H19) | I5: =SUBTOTAL(9,I6:I19) | J5: =SUBTOTAL(9,J6:J19) | ... O5: =SUBTOTAL(9,O6:O19)
A6: A1 | B6: Corrispettivi | C6: =SUBTOTAL(9,C7:C8) | D6: =SUBTOTAL(9,D7:D8) | E6: =SUBTOTAL(9,E7:E8) | F6: =SUBTOTAL(9,F7:F8) | G6: =SUBTOTAL(9,G7:G8) | H6: =SUBTOTAL(9,H7:H8) | I6: =SUBTOTAL(9,I7:I8) | J6: =SUBTOTAL(9,J7:J8) | ... O6: =SUBTOTAL(9,O7:O8)
A7: 10.01 | B7: Corrispettivi | O7: =SUM(C7:N7)
A8: 10.09 | B8: Resi, sconti e abbuoni su vendite | O8: =SUM(C8:N8)
A9: A2 | B9: Eventi | C9: =SUBTOTAL(9,C10:C11) | D9: =SUBTOTAL(9,D10:D11) | E9: =SUBTOTAL(9,E10:E11) | F9: =SUBTOTAL(9,F10:F11) | G9: =SUBTOTAL(9,G10:G11) | H9: =SUBTOTAL(9,H10:H11) | I9: =SUBTOTAL(9,I10:I11) | J9: =SUBTOTAL(9,J10:J11) | ... O9: =SUBTOTAL(9,O10:O11)
A10: 11.01 | B10: Ricavi eventi serali (ingressi e consumazioni) | O10: =SUM(C10:N10)
A11: 11.02 | B11: Ricavi eventi privati e compleanni | O11: =SUM(C11:N11)
A12: A3 | B12: Altri proventi | C12: =SUBTOTAL(9,C13:C19) | D12: =SUBTOTAL(9,D13:D19) | E12: =SUBTOTAL(9,E13:E19) | F12: =SUBTOTAL(9,F13:F19) | G12: =SUBTOTAL(9,G13:G19) | H12: =SUBTOTAL(9,H13:H19) | I12: =SUBTOTAL(9,I13:I19) | J12: =SUBTOTAL(9,J13:J19) | ... O12: =SUBTOTAL(9,O13:O19)
A13: 12.01 | B13: Proventi vari | O13: =SUM(C13:N13)
A14: 12.02 | B14: Contributi in conto esercizio | O14: =SUM(C14:N14)
A15: 12.03 | B15: Rimborsi assicurativi | O15: =SUM(C15:N15)
A16: 12.04 | B16: Premi, bonus e contributi da fornitori | O16: =SUM(C16:N16)
A17: 12.06 | B17: Sopravvenienze attive | O17: =SUM(C17:N17)
A18: 13.01 | B18: Interessi attivi bancari | O18: =SUM(C18:N18)
A19: 13.02 | B19: Altri proventi finanziari | O19: =SUM(C19:N19)
A21: B | B21: COSTO DEL VENDUTO | C21: =SUBTOTAL(9,C22:C51) | D21: =SUBTOTAL(9,D22:D51) | E21: =SUBTOTAL(9,E22:E51) | F21: =SUBTOTAL(9,F22:F51) | G21: =SUBTOTAL(9,G22:G51) | H21: =SUBTOTAL(9,H22:H51) | I21: =SUBTOTAL(9,I22:I51) | J21: =SUBTOTAL(9,J22:J51) | ... O21: =SUBTOTAL(9,O22:O51)
A22: B1 | B22: Beverage alcolico | C22: =SUBTOTAL(9,C23:C27) | D22: =SUBTOTAL(9,D23:D27) | E22: =SUBTOTAL(9,E23:E27) | F22: =SUBTOTAL(9,F23:F27) | G22: =SUBTOTAL(9,G23:G27) | H22: =SUBTOTAL(9,H23:H27) | I22: =SUBTOTAL(9,I23:I27) | J22: =SUBTOTAL(9,J23:J27) | ... O22: =SUBTOTAL(9,O23:O27)
A23: 20.1.01 | B23: Birra fusto | O23: =SUM(C23:N23)
A24: 20.1.02 | B24: Birra bottiglia e lattina | O24: =SUM(C24:N24)
A25: 20.1.03 | B25: Distillati e liquori | O25: =SUM(C25:N25)
A26: 20.1.04 | B26: Vermouth, bitter e aperitivi | O26: =SUM(C26:N26)
A27: 20.1.05 | B27: Vini | O27: =SUM(C27:N27)
A28: B2 | B28: Beverage analcolico | C28: =SUBTOTAL(9,C29:C32) | D28: =SUBTOTAL(9,D29:D32) | E28: =SUBTOTAL(9,E29:E32) | F28: =SUBTOTAL(9,F29:F32) | G28: =SUBTOTAL(9,G29:G32) | H28: =SUBTOTAL(9,H29:H32) | I28: =SUBTOTAL(9,I29:I32) | J28: =SUBTOTAL(9,J29:J32) | ... O28: =SUBTOTAL(9,O29:O32)
A29: 20.2.01 | B29: Bibite e soft drink | O29: =SUM(C29:N29)
A30: 20.2.02 | B30: Acqua minerale | O30: =SUM(C30:N30)
A31: 20.2.03 | B31: Succhi, nettari e centrifugati | O31: =SUM(C31:N31)
A32: 20.2.04 | B32: Sciroppi, purea e mixer | O32: =SUM(C32:N32)
A33: B3 | B33: Caffetteria | C33: =SUBTOTAL(9,C34:C37) | D33: =SUBTOTAL(9,D34:D37) | E33: =SUBTOTAL(9,E34:E37) | F33: =SUBTOTAL(9,F34:F37) | G33: =SUBTOTAL(9,G34:G37) | H33: =SUBTOTAL(9,H34:H37) | I33: =SUBTOTAL(9,I34:I37) | J33: =SUBTOTAL(9,J34:J37) | ... O33: =SUBTOTAL(9,O34:O37)
A34: 20.3.01 | B34: Caffè | O34: =SUM(C34:N34)
A35: 20.3.02 | B35: Latte e derivati | O35: =SUM(C35:N35)
A36: 20.3.03 | B36: Tè, infusi e cioccolata | O36: =SUM(C36:N36)
A37: 20.3.04 | B37: Zucchero e complementi caffetteria | O37: =SUM(C37:N37)
A38: B4 | B38: Food | C38: =SUBTOTAL(9,C39:C43) | D38: =SUBTOTAL(9,D39:D43) | E38: =SUBTOTAL(9,E39:E43) | F38: =SUBTOTAL(9,F39:F43) | G38: =SUBTOTAL(9,G39:G43) | H38: =SUBTOTAL(9,H39:H43) | I38: =SUBTOTAL(9,I39:I43) | J38: =SUBTOTAL(9,J39:J43) | ... O38: =SUBTOTAL(9,O39:O43)
A39: 20.4.01 | B39: Beni alimentari e gastronomia | O39: =SUM(C39:N39)
A40: 20.4.02 | B40: Frutta e verdura | O40: =SUM(C40:N40)
A41: 20.4.03 | B41: Pane e prodotti da forno | O41: =SUM(C41:N41)
A42: 20.4.04 | B42: Pasticceria e dolci | O42: =SUM(C42:N42)
...

Sheet SCOSTAMENTO
A1: SCOSTAMENTO — consuntivo contro budget
A2: Differenza in euro e in percentuale. Le righe rispecchiano una per una quelle di CASH FLOW e BUDGET: stessa altezza, stessi codici.
A4: Codice | B4: Voce | C4: GEN | D4: FEB | E4: MAR | F4: APR | G4: MAG | H4: GIU | I4: LUG | J4: AGO | K4: SET | L4: OTT | M4: NOV | N4: DIC | O4: TOTALE | Q4: Scost. %
A5: ='CASH FLOW'!A5 | B5: ='CASH FLOW'!B5 | C5: =IF(AND('CASH FLOW'!C5=0,BUDGET!C5=0),"",'CASH FLOW'!C5-BUDGET!C5) | D5: =IF(AND('CASH FLOW'!D5=0,BUDGET!D5=0),"",'CASH FLOW'!D5-BUDGET!D5) | E5: =IF(AND('CASH FLOW'!E5=0,BUDGET!E5=0),"",'CASH FLOW'!E5-BUDGET!E5) | F5: =IF(AND('CASH FLOW'!F5=0,BUDGET!F5=0),"",'CASH FLOW'!F5-BUDGET!F5) | G5: =IF(AND('CASH FLOW'!G5=0,BUDGET!G5=0),"",'CASH FLOW'!G5-BUDGET!G5) | H5: =IF(AND('CASH FLOW'!H5=0,BUDGET!H5=0),"",'CASH FLOW'!H5-BUDGET!H5) | I5: =IF(AND('CASH FLOW'!I5=0,BUDGET!I5=0),"",'CASH FLOW'!I5-BUDGET!I5) | J5: =IF(AND('CASH FLOW'!J5=0,BUDGET!J5=0),"",'CASH FLOW'!J5-BUDGET!J5) | ... O5: =IF(AND('CASH FLOW'!O5=0,BUDGET!O5=0),"",'CASH FLOW'!O5-BUDGET!O5) | Q5: =IF(BUDGET!O5=0,"",('CASH FLOW'!O5-BUDGET!O5)/ABS(BUDGET!O5))
A6: ='CASH FLOW'!A6 | B6: ='CASH FLOW'!B6 | C6: =IF(AND('CASH FLOW'!C6=0,BUDGET!C6=0),"",'CASH FLOW'!C6-BUDGET!C6) | D6: =IF(AND('CASH FLOW'!D6=0,BUDGET!D6=0),"",'CASH FLOW'!D6-BUDGET!D6) | E6: =IF(AND('CASH FLOW'!E6=0,BUDGET!E6=0),"",'CASH FLOW'!E6-BUDGET!E6) | F6: =IF(AND('CASH FLOW'!F6=0,BUDGET!F6=0),"",'CASH FLOW'!F6-BUDGET!F6) | G6: =IF(AND('CASH FLOW'!G6=0,BUDGET!G6=0),"",'CASH FLOW'!G6-BUDGET!G6) | H6: =IF(AND('CASH FLOW'!H6=0,BUDGET!H6=0),"",'CASH FLOW'!H6-BUDGET!H6) | I6: =IF(AND('CASH FLOW'!I6=0,BUDGET!I6=0),"",'CASH FLOW'!I6-BUDGET!I6) | J6: =IF(AND('CASH FLOW'!J6=0,BUDGET!J6=0),"",'CASH FLOW'!J6-BUDGET!J6) | ... O6: =IF(AND('CASH FLOW'!O6=0,BUDGET!O6=0),"",'CASH FLOW'!O6-BUDGET!O6) | Q6: =IF(BUDGET!O6=0,"",('CASH FLOW'!O6-BUDGET!O6)/ABS(BUDGET!O6))
A7: ='CASH FLOW'!A7 | B7: ='CASH FLOW'!B7 | C7: =IF(AND('CASH FLOW'!C7=0,BUDGET!C7=0),"",'CASH FLOW'!C7-BUDGET!C7) | D7: =IF(AND('CASH FLOW'!D7=0,BUDGET!D7=0),"",'CASH FLOW'!D7-BUDGET!D7) | E7: =IF(AND('CASH FLOW'!E7=0,BUDGET!E7=0),"",'CASH FLOW'!E7-BUDGET!E7) | F7: =IF(AND('CASH FLOW'!F7=0,BUDGET!F7=0),"",'CASH FLOW'!F7-BUDGET!F7) | G7: =IF(AND('CASH FLOW'!G7=0,BUDGET!G7=0),"",'CASH FLOW'!G7-BUDGET!G7) | H7: =IF(AND('CASH FLOW'!H7=0,BUDGET!H7=0),"",'CASH FLOW'!H7-BUDGET!H7) | I7: =IF(AND('CASH FLOW'!I7=0,BUDGET!I7=0),"",'CASH FLOW'!I7-BUDGET!I7) | J7: =IF(AND('CASH FLOW'!J7=0,BUDGET!J7=0),"",'CASH FLOW'!J7-BUDGET!J7) | ... O7: =IF(AND('CASH FLOW'!O7=0,BUDGET!O7=0),"",'CASH FLOW'!O7-BUDGET!O7) | Q7: =IF(BUDGET!O7=0,"",('CASH FLOW'!O7-BUDGET!O7)/ABS(BUDGET!O7))
A8: ='CASH FLOW'!A8 | B8: ='CASH FLOW'!B8 | C8: =IF(AND('CASH FLOW'!C8=0,BUDGET!C8=0),"",'CASH FLOW'!C8-BUDGET!C8) | D8: =IF(AND('CASH FLOW'!D8=0,BUDGET!D8=0),"",'CASH FLOW'!D8-BUDGET!D8) | E8: =IF(AND('CASH FLOW'!E8=0,BUDGET!E8=0),"",'CASH FLOW'!E8-BUDGET!E8) | F8: =IF(AND('CASH FLOW'!F8=0,BUDGET!F8=0),"",'CASH FLOW'!F8-BUDGET!F8) | G8: =IF(AND('CASH FLOW'!G8=0,BUDGET!G8=0),"",'CASH FLOW'!G8-BUDGET!G8) | H8: =IF(AND('CASH FLOW'!H8=0,BUDGET!H8=0),"",'CASH FLOW'!H8-BUDGET!H8) | I8: =IF(AND('CASH FLOW'!I8=0,BUDGET!I8=0),"",'CASH FLOW'!I8-BUDGET!I8) | J8: =IF(AND('CASH FLOW'!J8=0,BUDGET!J8=0),"",'CASH FLOW'!J8-BUDGET!J8) | ... O8: =IF(AND('CASH FLOW'!O8=0,BUDGET!O8=0),"",'CASH FLOW'!O8-BUDGET!O8) | Q8: =IF(BUDGET!O8=0,"",('CASH FLOW'!O8-BUDGET!O8)/ABS(BUDGET!O8))
A9: ='CASH FLOW'!A9 | B9: ='CASH FLOW'!B9 | C9: =IF(AND('CASH FLOW'!C9=0,BUDGET!C9=0),"",'CASH FLOW'!C9-BUDGET!C9) | D9: =IF(AND('CASH FLOW'!D9=0,BUDGET!D9=0),"",'CASH FLOW'!D9-BUDGET!D9) | E9: =IF(AND('CASH FLOW'!E9=0,BUDGET!E9=0),"",'CASH FLOW'!E9-BUDGET!E9) | F9: =IF(AND('CASH FLOW'!F9=0,BUDGET!F9=0),"",'CASH FLOW'!F9-BUDGET!F9) | G9: =IF(AND('CASH FLOW'!G9=0,BUDGET!G9=0),"",'CASH FLOW'!G9-BUDGET!G9) | H9: =IF(AND('CASH FLOW'!H9=0,BUDGET!H9=0),"",'CASH FLOW'!H9-BUDGET!H9) | I9: =IF(AND('CASH FLOW'!I9=0,BUDGET!I9=0),"",'CASH FLOW'!I9-BUDGET!I9) | J9: =IF(AND('CASH FLOW'!J9=0,BUDGET!J9=0),"",'CASH FLOW'!J9-BUDGET!J9) | ... O9: =IF(AND('CASH FLOW'!O9=0,BUDGET!O9=0),"",'CASH FLOW'!O9-BUDGET!O9) | Q9: =IF(BUDGET!O9=0,"",('CASH FLOW'!O9-BUDGET!O9)/ABS(BUDGET!O9))
A10: ='CASH FLOW'!A10 | B10: ='CASH FLOW'!B10 | C10: =IF(AND('CASH FLOW'!C10=0,BUDGET!C10=0),"",'CASH FLOW'!C10-BUDGET!C10) | D10: =IF(AND('CASH FLOW'!D10=0,BUDGET!D10=0),"",'CASH FLOW'!D10-BUDGET!D10) | E10: =IF(AND('CASH FLOW'!E10=0,BUDGET!E10=0),"",'CASH FLOW'!E10-BUDGET!E10) | F10: =IF(AND('CASH FLOW'!F10=0,BUDGET!F10=0),"",'CASH FLOW'!F10-BUDGET!F10) | G10: =IF(AND('CASH FLOW'!G10=0,BUDGET!G10=0),"",'CASH FLOW'!G10-BUDGET!G10) | H10: =IF(AND('CASH FLOW'!H10=0,BUDGET!H10=0),"",'CASH FLOW'!H10-BUDGET!H10) | I10: =IF(AND('CASH FLOW'!I10=0,BUDGET!I10=0),"",'CASH FLOW'!I10-BUDGET!I10) | J10: =IF(AND('CASH FLOW'!J10=0,BUDGET!J10=0),"",'CASH FLOW'!J10-BUDGET!J10) | ... O10: =IF(AND('CASH FLOW'!O10=0,BUDGET!O10=0),"",'CASH FLOW'!O10-BUDGET!O10) | Q10: =IF(BUDGET!O10=0,"",('CASH FLOW'!O10-BUDGET!O10)/ABS(BUDGET!O10))
A11: ='CASH FLOW'!A11 | B11: ='CASH FLOW'!B11 | C11: =IF(AND('CASH FLOW'!C11=0,BUDGET!C11=0),"",'CASH FLOW'!C11-BUDGET!C11) | D11: =IF(AND('CASH FLOW'!D11=0,BUDGET!D11=0),"",'CASH FLOW'!D11-BUDGET!D11) | E11: =IF(AND('CASH FLOW'!E11=0,BUDGET!E11=0),"",'CASH FLOW'!E11-BUDGET!E11) | F11: =IF(AND('CASH FLOW'!F11=0,BUDGET!F11=0),"",'CASH FLOW'!F11-BUDGET!F11) | G11: =IF(AND('CASH FLOW'!G11=0,BUDGET!G11=0),"",'CASH FLOW'!G11-BUDGET!G11) | H11: =IF(AND('CASH FLOW'!H11=0,BUDGET!H11=0),"",'CASH FLOW'!H11-BUDGET!H11) | I11: =IF(AND('CASH FLOW'!I11=0,BUDGET!I11=0),"",'CASH FLOW'!I11-BUDGET!I11) | J11: =IF(AND('CASH FLOW'!J11=0,BUDGET!J11=0),"",'CASH FLOW'!J11-BUDGET!J11) | ... O11: =IF(AND('CASH FLOW'!O11=0,BUDGET!O11=0),"",'CASH FLOW'!O11-BUDGET!O11) | Q11: =IF(BUDGET!O11=0,"",('CASH FLOW'!O11-BUDGET!O11)/ABS(BUDGET!O11))
A12: ='CASH FLOW'!A12 | B12: ='CASH FLOW'!B12 | C12: =IF(AND('CASH FLOW'!C12=0,BUDGET!C12=0),"",'CASH FLOW'!C12-BUDGET!C12) | D12: =IF(AND('CASH FLOW'!D12=0,BUDGET!D12=0),"",'CASH FLOW'!D12-BUDGET!D12) | E12: =IF(AND('CASH FLOW'!E12=0,BUDGET!E12=0),"",'CASH FLOW'!E12-BUDGET!E12) | F12: =IF(AND('CASH FLOW'!F12=0,BUDGET!F12=0),"",'CASH FLOW'!F12-BUDGET!F12) | G12: =IF(AND('CASH FLOW'!G12=0,BUDGET!G12=0),"",'CASH FLOW'!G12-BUDGET!G12) | H12: =IF(AND('CASH FLOW'!H12=0,BUDGET!H12=0),"",'CASH FLOW'!H12-BUDGET!H12) | I12: =IF(AND('CASH FLOW'!I12=0,BUDGET!I12=0),"",'CASH FLOW'!I12-BUDGET!I12) | J12: =IF(AND('CASH FLOW'!J12=0,BUDGET!J12=0),"",'CASH FLOW'!J12-BUDGET!J12) | ... O12: =IF(AND('CASH FLOW'!O12=0,BUDGET!O12=0),"",'CASH FLOW'!O12-BUDGET!O12) | Q12: =IF(BUDGET!O12=0,"",('CASH FLOW'!O12-BUDGET!O12)/ABS(BUDGET!O12))
A13: ='CASH FLOW'!A13 | B13: ='CASH FLOW'!B13 | C13: =IF(AND('CASH FLOW'!C13=0,BUDGET!C13=0),"",'CASH FLOW'!C13-BUDGET!C13) | D13: =IF(AND('CASH FLOW'!D13=0,BUDGET!D13=0),"",'CASH FLOW'!D13-BUDGET!D13) | E13: =IF(AND('CASH FLOW'!E13=0,BUDGET!E13=0),"",'CASH FLOW'!E13-BUDGET!E13) | F13: =IF(AND('CASH FLOW'!F13=0,BUDGET!F13=0),"",'CASH FLOW'!F13-BUDGET!F13) | G13: =IF(AND('CASH FLOW'!G13=0,BUDGET!G13=0),"",'CASH FLOW'!G13-BUDGET!G13) | H13: =IF(AND('CASH FLOW'!H13=0,BUDGET!H13=0),"",'CASH FLOW'!H13-BUDGET!H13) | I13: =IF(AND('CASH FLOW'!I13=0,BUDGET!I13=0),"",'CASH FLOW'!I13-BUDGET!I13) | J13: =IF(AND('CASH FLOW'!J13=0,BUDGET!J13=0),"",'CASH FLOW'!J13-BUDGET!J13) | ... O13: =IF(AND('CASH FLOW'!O13=0,BUDGET!O13=0),"",'CASH FLOW'!O13-BUDGET!O13) | Q13: =IF(BUDGET!O13=0,"",('CASH FLOW'!O13-BUDGET!O13)/ABS(BUDGET!O13))
A14: ='CASH FLOW'!A14 | B14: ='CASH FLOW'!B14 | C14: =IF(AND('CASH FLOW'!C14=0,BUDGET!C14=0),"",'CASH FLOW'!C14-BUDGET!C14) | D14: =IF(AND('CASH FLOW'!D14=0,BUDGET!D14=0),"",'CASH FLOW'!D14-BUDGET!D14) | E14: =IF(AND('CASH FLOW'!E14=0,BUDGET!E14=0),"",'CASH FLOW'!E14-BUDGET!E14) | F14: =IF(AND('CASH FLOW'!F14=0,BUDGET!F14=0),"",'CASH FLOW'!F14-BUDGET!F14) | G14: =IF(AND('CASH FLOW'!G14=0,BUDGET!G14=0),"",'CASH FLOW'!G14-BUDGET!G14) | H14: =IF(AND('CASH FLOW'!H14=0,BUDGET!H14=0),"",'CASH FLOW'!H14-BUDGET!H14) | I14: =IF(AND('CASH FLOW'!I14=0,BUDGET!I14=0),"",'CASH FLOW'!I14-BUDGET!I14) | J14: =IF(AND('CASH FLOW'!J14=0,BUDGET!J14=0),"",'CASH FLOW'!J14-BUDGET!J14) | ... O14: =IF(AND('CASH FLOW'!O14=0,BUDGET!O14=0),"",'CASH FLOW'!O14-BUDGET!O14) | Q14: =IF(BUDGET!O14=0,"",('CASH FLOW'!O14-BUDGET!O14)/ABS(BUDGET!O14))
A15: ='CASH FLOW'!A15 | B15: ='CASH FLOW'!B15 | C15: =IF(AND('CASH FLOW'!C15=0,BUDGET!C15=0),"",'CASH FLOW'!C15-BUDGET!C15) | D15: =IF(AND('CASH FLOW'!D15=0,BUDGET!D15=0),"",'CASH FLOW'!D15-BUDGET!D15) | E15: =IF(AND('CASH FLOW'!E15=0,BUDGET!E15=0),"",'CASH FLOW'!E15-BUDGET!E15) | F15: =IF(AND('CASH FLOW'!F15=0,BUDGET!F15=0),"",'CASH FLOW'!F15-BUDGET!F15) | G15: =IF(AND('CASH FLOW'!G15=0,BUDGET!G15=0),"",'CASH FLOW'!G15-BUDGET!G15) | H15: =IF(AND('CASH FLOW'!H15=0,BUDGET!H15=0),"",'CASH FLOW'!H15-BUDGET!H15) | I15: =IF(AND('CASH FLOW'!I15=0,BUDGET!I15=0),"",'CASH FLOW'!I15-BUDGET!I15) | J15: =IF(AND('CASH FLOW'!J15=0,BUDGET!J15=0),"",'CASH FLOW'!J15-BUDGET!J15) | ... O15: =IF(AND('CASH FLOW'!O15=0,BUDGET!O15=0),"",'CASH FLOW'!O15-BUDGET!O15) | Q15: =IF(BUDGET!O15=0,"",('CASH FLOW'!O15-BUDGET!O15)/ABS(BUDGET!O15))
A16: ='CASH FLOW'!A16 | B16: ='CASH FLOW'!B16 | C16: =IF(AND('CASH FLOW'!C16=0,BUDGET!C16=0),"",'CASH FLOW'!C16-BUDGET!C16) | D16: =IF(AND('CASH FLOW'!D16=0,BUDGET!D16=0),"",'CASH FLOW'!D16-BUDGET!D16) | E16: =IF(AND('CASH FLOW'!E16=0,BUDGET!E16=0),"",'CASH FLOW'!E16-BUDGET!E16) | F16: =IF(AND('CASH FLOW'!F16=0,BUDGET!F16=0),"",'CASH FLOW'!F16-BUDGET!F16) | G16: =IF(AND('CASH FLOW'!G16=0,BUDGET!G16=0),"",'CASH FLOW'!G16-BUDGET!G16) | H16: =IF(AND('CASH FLOW'!H16=0,BUDGET!H16=0),"",'CASH FLOW'!H16-BUDGET!H16) | I16: =IF(AND('CASH FLOW'!I16=0,BUDGET!I16=0),"",'CASH FLOW'!I16-BUDGET!I16) | J16: =IF(AND('CASH FLOW'!J16=0,BUDGET!J16=0),"",'CASH FLOW'!J16-BUDGET!J16) | ... O16: =IF(AND('CASH FLOW'!O16=0,BUDGET!O16=0),"",'CASH FLOW'!O16-BUDGET!O16) | Q16: =IF(BUDGET!O16=0,"",('CASH FLOW'!O16-BUDGET!O16)/ABS(BUDGET!O16))
... A222: ='CASH FLOW'!A222 | B222: ='CASH FLOW'!B222 | C222: =IF(AND('CASH FLOW'!C222=0,BUDGET!C222=0),"",'CASH FLOW'!C222-BUDGET!C222) | D222: =IF(AND('CASH FLOW'!D222=0,BUDGET!D222=0),"",'CASH FLOW'!D222-BUDGET!D222) | E222: =IF(AND('CASH FLOW'!E222=0,BUDGET!E222=0),"",'CASH FLOW'!E222-BUDGET!E222) | F222: =IF(AND('CASH FLOW'!F222=0,BUDGET!F222=0),"",'CASH FLOW'!F222-BUDGET!F222) | G222: =IF(AND('CASH FLOW'!G222=0,BUDGET!G222=0),"",'CASH FLOW'!G222-BUDGET!G222) | H222: =IF(AND('CASH FLOW'!H222=0,BUDGET!H222=0),"",'CASH FLOW'!H222-BUDGET!H222) | I222: =IF(AND('CASH FLOW'!I222=0,BUDGET!I222=0),"",'CASH FLOW'!I222-BUDGET!I222) | J222: =IF(AND('CASH FLOW'!J222=0,BUDGET!J222=0),"",'CASH FLOW'!J222-BUDGET!J222) | ... O222: =IF(AND('CASH FLOW'!O222=0,BUDGET!O222=0),"",'CASH FLOW'!O222-BUDGET!O222) | Q222: =IF(BUDGET!O222=0,"",('CASH FLOW'!O222-BUDGET!O222)/ABS(BUDGET!O222))

Sheet PER CENTRO
A1: LETTURA PER CENTRO DI COSTO — totali dell'anno
A2: Il centro segue l'attivita', non il conto corrente. I costi comuni restano su STR: il ribaltamento in fondo e' un calcolo di analisi, non scrive movimenti.
A4: Codice | B4: Voce | C4: STR | D4: WEISS | E4: VV | F4: CAS | G4: TOTALE | I4: Quadratura
A5: A | B5: INCASSI OPERATIVI | C5: =SUM(C6:C8) | D5: =SUM(D6:D8) | E5: =SUM(E6:E8) | F5: =SUM(F6:F8) | G5: =SUM(G6:G8) | I5: =IF(ROUND(G5-'CASH FLOW'!O5,2)=0,"ok","non torna")
A6: A1 | B6: Corrispettivi | G6: =SUM(C6:F6)
A7: A2 | B7: Eventi | G7: =SUM(C7:F7)
A8: A3 | B8: Altri proventi | G8: =SUM(C8:F8)
A10: B | B10: COSTO DEL VENDUTO | C10: =SUM(C11:C16) | D10: =SUM(D11:D16) | E10: =SUM(E11:E16) | F10: =SUM(F11:F16) | G10: =SUM(G11:G16) | I10: =IF(ROUND(G10-'CASH FLOW'!O21,2)=0,"ok","non torna")
A11: B1 | B11: Beverage alcolico | G11: =SUM(C11:F11)
A12: B2 | B12: Beverage analcolico | G12: =SUM(C12:F12)
A13: B3 | B13: Caffetteria | G13: =SUM(C13:F13)
A14: B4 | B14: Food | G14: =SUM(C14:F14)
A15: B5 | B15: Consumabili di servizio | G15: =SUM(C15:F15)
A16: B6 | B16: Rettifiche su acquisti | G16: =SUM(C16:F16)
A18: C | B18: COSTO DEL PERSONALE | C18: =SUM(C19:C23) | D18: =SUM(D19:D23) | E18: =SUM(E19:E23) | F18: =SUM(F19:F23) | G18: =SUM(G19:G23) | I18: =IF(ROUND(G18-'CASH FLOW'!O54,2)=0,"ok","non torna")
A19: C1 | B19: Retribuzioni | G19: =SUM(C19:F19)
A20: C2 | B20: Oneri sociali | G20: =SUM(C20:F20)
A21: C3 | B21: TFR corrisposto | G21: =SUM(C21:F21)
A22: C4 | B22: Altri costi del personale | G22: =SUM(C22:F22)
A23: C5 | B23: Organi sociali e collaborazioni | G23: =SUM(C23:F23)
A25: D | B25: COSTI DIRETTI EVENTI | C25: =SUM(C26:C29) | D25: =SUM(D26:D29) | E25: =SUM(E26:E29) | F25: =SUM(F26:F29) | G25: =SUM(G26:G29) | I25: =IF(ROUND(G25-'CASH FLOW'!O83,2)=0,"ok","non torna")
A26: D1 | B26: Artisti e service | G26: =SUM(C26:F26)
A27: D2 | B27: Manodopera evento | G27: =SUM(C27:F27)
A28: D3 | B28: Promozione evento | G28: =SUM(C28:F28)
A29: D4 | B29: Oneri e allestimenti evento | G29: =SUM(C29:F29)
A31: E | B31: COSTI DI STRUTTURA | C31: =SUM(C32:C39) | D31: =SUM(D32:D39) | E31: =SUM(E32:E39) | F31: =SUM(F32:F39) | G31: =SUM(G32:G39) | I31: =IF(ROUND(G31-'CASH FLOW'!O100,2)=0,"ok","non torna")
A32: E1 | B32: Immobili e spazi | G32: =SUM(C32:F32)
A33: E2 | B33: Utenze | G33: =SUM(C33:F33)
A34: E3 | B34: Noleggi, leasing e licenze | G34: =SUM(C34:F34)
A35: E4 | B35: Manutenzioni e servizi operativi | G35: =SUM(C35:F35)
A36: E5 | B36: Attrezzatura e allestimenti | G36: =SUM(C36:F36)
A37: E6 | B37: Servizi professionali e amministrativi | G37: =SUM(C37:F37)
A38: E7 | B38: Marketing e comunicazione | G38: =SUM(C38:F38)
A39: E8 | B39: Tributi, assicurazioni e oneri diversi | G39: =SUM(C39:F39)
A41: F | B41: ONERI FINANZIARI | C41: =SUM(C42:C44) | D41: =SUM(D42:D44) | E41: =SUM(E42:E44) | F41: =SUM(F42:F44) | G41: =SUM(G42:G44) | I41: =IF(ROUND(G41-'CASH FLOW'!O166,2)=0,"ok","non torna")
A42: F1 | B42: Interessi passivi | G42: =SUM(C42:F42)
A43: F2 | B43: Spese e servizi bancari | G43: =SUM(C43:F43)
A44: F3 | B44: Commissioni su incassi | G44: =SUM(C44:F44)
A46: G | B46: FISCO E IVA | C46: =SUM(C47:C51) | D46: =SUM(D47:D51) | E46: =SUM(E47:E51) | F46: =SUM(F47:F51) | G46: =SUM(G47:G51) | I46: =IF(ROUND(G46-'CASH FLOW'!O185,2)=0,"ok","non torna")
A47: G1 | B47: IVA incassata sui corrispettivi | G47: =SUM(C47:F47)
...

Sheet SINTESI
A1: SINTESI — indicatori dell'anno
A2: Tutti gli indicatori leggono la colonna TOTALE del foglio CASH FLOW.
B4: VOLUMI
B5: Incassi operativi | C5: ='CASH FLOW'!O5 | D5: Corrispettivi, eventi e altri proventi, al netto IVA
B6: Giorni di apertura | D6: Da compilare: serve alla media giornaliera
B7: Incasso medio giornaliero | C7: =IF(C6=0,"",C5/C6) | D7: Incassi operativi diviso giorni di apertura
B9: MARGINI
B10: Margine di contribuzione | C10: ='CASH FLOW'!O52 | D10: Incassi meno costo del venduto
B11: Margine di contribuzione % | C11: =IF('CASH FLOW'!O5=0,"",'CASH FLOW'!O52/'CASH FLOW'!O5)
B12: Incidenza costo del venduto | C12: =IF('CASH FLOW'!O5=0,"",-'CASH FLOW'!O21/'CASH FLOW'!O5) | D12: Beverage, caffetteria, food e consumabili sugli incassi
B13: Incidenza manodopera completa | C13: =IF('CASH FLOW'!O5=0,"",-'CASH FLOW'!O219/'CASH FLOW'!O5) | D13: Dalla riga memo: comprende personale eventi, ritenute e contributi
B14: Incidenza commissioni su incassi | C14: =IF('CASH FLOW'!O6=0,"",-'CASH FLOW'!O177/'CASH FLOW'!O6) | D14: Pagobancomat, carte, SumUp, Axerve sui corrispettivi
B16: CASH FLOW
B17: Cash flow operativo | C17: ='CASH FLOW'!O183 | D17: Prima di fisco, investimenti e finanziamenti
B18: Cash flow operativo % | C18: =IF('CASH FLOW'!O5=0,"",'CASH FLOW'!O183/'CASH FLOW'!O5)
B19: Variazione di cassa | C19: ='CASH FLOW'!O213
B20: Cassa e banca a inizio anno | C20: ='CASH FLOW'!C214
B21: Cassa e banca a fine anno | C21: ='CASH FLOW'!N215
B23: EVENTI
B24: Ricavi eventi | C24: ='CASH FLOW'!O9
B25: Margine eventi | C25: ='CASH FLOW'!O220 | D25: Ricavi eventi meno costi diretti eventi
B26: Peso eventi sugli incassi | C26: =IF('CASH FLOW'!O5=0,"",'CASH FLOW'!O9/'CASH FLOW'!O5)
B28: TENUTA
B29: Costi di struttura mensili medi | C29: =-'CASH FLOW'!O100/12 | D29: Media dei dodici mesi
B30: Mesi di struttura coperti dalla cassa | C30: =IF(C29=0,"",C21/C29) | D30: Cassa finale diviso costi di struttura mensili
